<robot name="g1_29dof_rev_1_0_with_inspire_hand_DFQ">
  <material name="dark">
    <color rgba="0.2 0.2 0.2 1"/>
  </material>
  <material name="white">
    <color rgba="0.7 0.7 0.7 1"/>
  </material>

  <mujoco>
    <compiler meshdir="meshes" discardvisual="false"/>
  </mujoco>


  <link name="pelvis">
    <inertial>
      <origin xyz="0 0 -0.07605" rpy="0 0 0"/>
      <mass value="3.813"/>
      <inertia ixx="0.010549" ixy="0" ixz="2.1E-06" iyy="0.0093089" iyz="0" izz="0.0079184"/>
    </inertial>
    <visual>
      <origin xyz="0 0 0" rpy="0 0 0"/>
      <geometry>
        <mesh filename="meshes/pelvis.STL"/>
      </geometry>
      <material name="dark"/>
    </visual>
  </link>
  <link name="pelvis_contour_link">
    <inertial>
      <origin xyz="0 0 0" rpy="0 0 0"/>
      <mass value="0.001"/>
      <inertia ixx="1e-7" ixy="0" ixz="0" iyy="1e-7" iyz="0" izz="1e-7"/>
    </inertial>
    <visual>
      <origin xyz="0 0 0" rpy="0 0 0"/>
      <geometry>
        <mesh filename="meshes/pelvis_contour_link.STL"/>
      </geometry>
      <material name="white"/>
    </visual>
    <collision>
      <origin xyz="0 0 0" rpy="0 0 0"/>
      <geometry>
        <mesh filename="meshes/pelvis_contour_link.STL"/>
      </geometry>
    </collision>
  </link>
  <joint name="pelvis_contour_joint" type="fixed">
    <parent link="pelvis"/>
    <child link="pelvis_contour_link"/>
  </joint>


  <link name="left_hip_pitch_link">
    <inertial>
      <origin xyz="0.002741 0.047791 -0.02606" rpy="0 0 0"/>
      <mass value="1.35"/>
      <inertia ixx="0.001811" ixy="3.68E-05" ixz="-3.44E-05" iyy="0.0014193" iyz="0.000171" izz="0.0012812"/>
    </inertial>
    <visual>
      <origin xyz="0 0 0" rpy="0 0 0"/>
      <geometry>
        <mesh filename="meshes/left_hip_pitch_link.STL"/>
      </geometry>
      <material name="dark"/>
    </visual>
    <collision>
      <origin xyz="0 0 0" rpy="0 0 0"/>
      <geometry>
        <mesh filename="meshes/left_hip_pitch_link.STL"/>
      </geometry>
    </collision>
  </link>
  <joint name="left_hip_pitch_joint" type="revolute">
    <origin xyz="0 0.064452 -0.1027" rpy="0 0 0"/>
    <parent link="pelvis"/>
    <child link="left_hip_pitch_link"/>
    <axis xyz="0 1 0"/>
    <limit lower="-2.5307" upper="2.8798" effort="88" velocity="32"/>
  </joint>
  <link name="left_hip_roll_link">
    <inertial>
      <origin xyz="0.029812 -0.001045 -0.087934" rpy="0 0 0"/>
      <mass value="1.52"/>
      <inertia ixx="0.0023773" ixy="-3.8E-06" ixz="-0.0003908" iyy="0.0024123" iyz="1.84E-05" izz="0.0016595"/>
    </inertial>
    <visual>
      <origin xyz="0 0 0" rpy="0 0 0"/>
      <geometry>
        <mesh filename="meshes/left_hip_roll_link.STL"/>
      </geometry>
      <material name="white"/>
    </visual>
    <collision>
      <origin xyz="0 0 0" rpy="0 0 0"/>
      <geometry>
        <mesh filename="meshes/left_hip_roll_link.STL"/>
      </geometry>
    </collision>
  </link>
  <joint name="left_hip_roll_joint" type="revolute">
    <origin xyz="0 0.052 -0.030465" rpy="0 -0.1749 0"/>
    <parent link="left_hip_pitch_link"/>
    <child link="left_hip_roll_link"/>
    <axis xyz="1 0 0"/>
    <limit lower="-0.5236" upper="2.9671" effort="139" velocity="20"/>
  </joint>
  <link name="left_hip_yaw_link">
    <inertial>
      <origin xyz="-0.057709 -0.010981 -0.15078" rpy="0 0 0"/>
      <mass value="1.702"/>
      <inertia ixx="0.0057774" ixy="-0.0005411" ixz="-0.0023948" iyy="0.0076124" iyz="-0.0007072" izz="0.003149"/>
    </inertial>
    <visual>
      <origin xyz="0 0 0" rpy="0 0 0"/>
      <geometry>
        <mesh filename="meshes/left_hip_yaw_link.STL"/>
      </geometry>
      <material name="white"/>
    </visual>
    <collision>
      <origin xyz="0 0 0" rpy="0 0 0"/>
      <geometry>
        <mesh filename="meshes/left_hip_yaw_link.STL"/>
      </geometry>
    </collision>
  </link>
  <joint name="left_hip_yaw_joint" type="revolute">
    <origin xyz="0.025001 0 -0.12412" rpy="0 0 0"/>
    <parent link="left_hip_roll_link"/>
    <child link="left_hip_yaw_link"/>
    <axis xyz="0 0 1"/>
    <limit lower="-2.7576" upper="2.7576" effort="88" velocity="32"/>
  </joint>
  <link name="left_knee_link">
    <inertial>
      <origin xyz="0.005457 0.003964 -0.12074" rpy="0 0 0"/>
      <mass value="1.932"/>
      <inertia ixx="0.011329" ixy="4.82E-05" ixz="-4.49E-05" iyy="0.011277" iyz="-0.0007146" izz="0.0015168"/>
    </inertial>
    <visual>
      <origin xyz="0 0 0" rpy="0 0 0"/>
      <geometry>
        <mesh filename="meshes/left_knee_link.STL"/>
      </geometry>
      <material name="white"/>
    </visual>
    <collision>
      <origin xyz="0 0 0" rpy="0 0 0"/>
      <geometry>
        <mesh filename="meshes/left_knee_link.STL"/>
      </geometry>
    </collision>
  </link>
  <joint name="left_knee_joint" type="revolute">
    <origin xyz="-0.078273 0.0021489 -0.17734" rpy="0 0.1749 0"/>
    <parent link="left_hip_yaw_link"/>
    <child link="left_knee_link"/>
    <axis xyz="0 1 0"/>
    <limit lower="-0.087267" upper="2.8798" effort="139" velocity="20"/>
  </joint>
  <link name="left_ankle_pitch_link">
    <inertial>
      <origin xyz="-0.007269 0 0.011137" rpy="0 0 0"/>
      <mass value="0.074"/>
      <inertia ixx="8.4E-06" ixy="0" ixz="-2.9E-06" iyy="1.89E-05" iyz="0" izz="1.26E-05"/>
    </inertial>
    <visual>
      <origin xyz="0 0 0" rpy="0 0 0"/>
      <geometry>
        <mesh filename="meshes/left_ankle_pitch_link.STL"/>
      </geometry>
      <material name="white"/>
    </visual>
    <collision>
      <origin xyz="0 0 0" rpy="0 0 0"/>
      <geometry>
        <mesh filename="meshes/left_ankle_pitch_link.STL"/>
      </geometry>
    </collision>
  </link>
  <joint name="left_ankle_pitch_joint" type="revolute">
    <origin xyz="0 -9.4445E-05 -0.30001" rpy="0 0 0"/>
    <parent link="left_knee_link"/>
    <child link="left_ankle_pitch_link"/>
    <axis xyz="0 1 0"/>
    <limit lower="-0.87267" upper="0.5236" effort="35" velocity="30"/>
  </joint>
  <link name="left_ankle_roll_link">
    <inertial>
      <origin xyz="0.026505 0 -0.016425" rpy="0 0 0"/>
      <mass value="0.608"/>
      <inertia ixx="0.0002231" ixy="2E-07" ixz="8.91E-05" iyy="0.0016161" iyz="-1E-07" izz="0.0016667"/>
    </inertial>
    <visual>
      <origin xyz="0 0 0" rpy="0 0 0"/>
      <geometry>
        <mesh filename="meshes/left_ankle_roll_link.STL"/>
      </geometry>
      <material name="dark"/>
    </visual>
    <collision>
      <origin xyz="-0.05 0.025 -0.03" rpy="0 0 0"/>
      <geometry>
        <sphere radius="0.005"/>
      </geometry>
    </collision>
    <collision>
      <origin xyz="-0.05 -0.025 -0.03" rpy="0 0 0"/>
      <geometry>
        <sphere radius="0.005"/>
      </geometry>
    </collision>
    <collision>
      <origin xyz="0.12 0.03 -0.03" rpy="0 0 0"/>
      <geometry>
        <sphere radius="0.005"/>
      </geometry>
    </collision>
    <collision>
      <origin xyz="0.12 -0.03 -0.03" rpy="0 0 0"/>
      <geometry>
        <sphere radius="0.005"/>
      </geometry>
    </collision>
  </link>
  <joint name="left_ankle_roll_joint" type="revolute">
    <origin xyz="0 0 -0.017558" rpy="0 0 0"/>
    <parent link="left_ankle_pitch_link"/>
    <child link="left_ankle_roll_link"/>
    <axis xyz="1 0 0"/>
    <limit lower="-0.2618" upper="0.2618" effort="35" velocity="30"/>
  </joint>
  <link name="right_hip_pitch_link">
    <inertial>
      <origin xyz="0.002741 -0.047791 -0.02606" rpy="0 0 0"/>
      <mass value="1.35"/>
      <inertia ixx="0.001811" ixy="-3.68E-05" ixz="-3.44E-05" iyy="0.0014193" iyz="-0.000171" izz="0.0012812"/>
    </inertial>
    <visual>
      <origin xyz="0 0 0" rpy="0 0 0"/>
      <geometry>
        <mesh filename="meshes/right_hip_pitch_link.STL"/>
      </geometry>
      <material name="dark"/>
    </visual>
    <collision>
      <origin xyz="0 0 0" rpy="0 0 0"/>
      <geometry>
        <mesh filename="meshes/right_hip_pitch_link.STL"/>
      </geometry>
    </collision>
  </link>
  <joint name="right_hip_pitch_joint" type="revolute">
    <origin xyz="0 -0.064452 -0.1027" rpy="0 0 0"/>
    <parent link="pelvis"/>
    <child link="right_hip_pitch_link"/>
    <axis xyz="0 1 0"/>
    <limit lower="-2.5307" upper="2.8798" effort="88" velocity="32"/>
  </joint>
  <link name="right_hip_roll_link">
    <inertial>
      <origin xyz="0.029812 0.001045 -0.087934" rpy="0 0 0"/>
      <mass value="1.52"/>
      <inertia ixx="0.0023773" ixy="3.8E-06" ixz="-0.0003908" iyy="0.0024123" iyz="-1.84E-05" izz="0.0016595"/>
    </inertial>
    <visual>
      <origin xyz="0 0 0" rpy="0 0 0"/>
      <geometry>
        <mesh filename="meshes/right_hip_roll_link.STL"/>
      </geometry>
      <material name="white"/>
    </visual>
    <collision>
      <origin xyz="0 0 0" rpy="0 0 0"/>
      <geometry>
        <mesh filename="meshes/right_hip_roll_link.STL"/>
      </geometry>
    </collision>
  </link>
  <joint name="right_hip_roll_joint" type="revolute">
    <origin xyz="0 -0.052 -0.030465" rpy="0 -0.1749 0"/>
    <parent link="right_hip_pitch_link"/>
    <child link="right_hip_roll_link"/>
    <axis xyz="1 0 0"/>
    <limit lower="-2.9671" upper="0.5236" effort="139" velocity="20"/>
  </joint>
  <link name="right_hip_yaw_link">
    <inertial>
      <origin xyz="-0.057709 0.010981 -0.15078" rpy="0 0 0"/>
      <mass value="1.702"/>
      <inertia ixx="0.0057774" ixy="0.0005411" ixz="-0.0023948" iyy="0.0076124" iyz="0.0007072" izz="0.003149"/>
    </inertial>
    <visual>
      <origin xyz="0 0 0" rpy="0 0 0"/>
      <geometry>
        <mesh filename="meshes/right_hip_yaw_link.STL"/>
      </geometry>
      <material name="white"/>
    </visual>
    <collision>
      <origin xyz="0 0 0" rpy="0 0 0"/>
      <geometry>
        <mesh filename="meshes/right_hip_yaw_link.STL"/>
      </geometry>
    </collision>
  </link>
  <joint name="right_hip_yaw_joint" type="revolute">
    <origin xyz="0.025001 0 -0.12412" rpy="0 0 0"/>
    <parent link="right_hip_roll_link"/>
    <child link="right_hip_yaw_link"/>
    <axis xyz="0 0 1"/>
    <limit lower="-2.7576" upper="2.7576" effort="88" velocity="32"/>
  </joint>
  <link name="right_knee_link">
    <inertial>
      <origin xyz="0.005457 -0.003964 -0.12074" rpy="0 0 0"/>
      <mass value="1.932"/>
      <inertia ixx="0.011329" ixy="-4.82E-05" ixz="4.49E-05" iyy="0.011277" iyz="0.0007146" izz="0.0015168"/>
    </inertial>
    <visual>
      <origin xyz="0 0 0" rpy="0 0 0"/>
      <geometry>
        <mesh filename="meshes/right_knee_link.STL"/>
      </geometry>
      <material name="white"/>
    </visual>
    <collision>
      <origin xyz="0 0 0" rpy="0 0 0"/>
      <geometry>
        <mesh filename="meshes/right_knee_link.STL"/>
      </geometry>
    </collision>
  </link>
  <joint name="right_knee_joint" type="revolute">
    <origin xyz="-0.078273 -0.0021489 -0.17734" rpy="0 0.1749 0"/>
    <parent link="right_hip_yaw_link"/>
    <child link="right_knee_link"/>
    <axis xyz="0 1 0"/>
    <limit lower="-0.087267" upper="2.8798" effort="139" velocity="20"/>
  </joint>
  <link name="right_ankle_pitch_link">
    <inertial>
      <origin xyz="-0.007269 0 0.011137" rpy="0 0 0"/>
      <mass value="0.074"/>
      <inertia ixx="8.4E-06" ixy="0" ixz="-2.9E-06" iyy="1.89E-05" iyz="0" izz="1.26E-05"/>
    </inertial>
    <visual>
      <origin xyz="0 0 0" rpy="0 0 0"/>
      <geometry>
        <mesh filename="meshes/right_ankle_pitch_link.STL"/>
      </geometry>
      <material name="white"/>
    </visual>
    <collision>
      <origin xyz="0 0 0" rpy="0 0 0"/>
      <geometry>
        <mesh filename="meshes/right_ankle_pitch_link.STL"/>
      </geometry>
    </collision>
  </link>
  <joint name="right_ankle_pitch_joint" type="revolute">
    <origin xyz="0 9.4445E-05 -0.30001" rpy="0 0 0"/>
    <parent link="right_knee_link"/>
    <child link="right_ankle_pitch_link"/>
    <axis xyz="0 1 0"/>
    <limit lower="-0.87267" upper="0.5236" effort="35" velocity="30"/>
  </joint>
  <link name="right_ankle_roll_link">
    <inertial>
      <origin xyz="0.026505 0 -0.016425" rpy="0 0 0"/>
      <mass value="0.608"/>
      <inertia ixx="0.0002231" ixy="-2E-07" ixz="8.91E-05" iyy="0.0016161" iyz="1E-07" izz="0.0016667"/>
    </inertial>
    <visual>
      <origin xyz="0 0 0" rpy="0 0 0"/>
      <geometry>
        <mesh filename="meshes/right_ankle_roll_link.STL"/>
      </geometry>
      <material name="dark"/>
    </visual>
    <collision>
      <origin xyz="-0.05 0.025 -0.03" rpy="0 0 0"/>
      <geometry>
        <sphere radius="0.005"/>
      </geometry>
    </collision>
    <collision>
      <origin xyz="-0.05 -0.025 -0.03" rpy="0 0 0"/>
      <geometry>
        <sphere radius="0.005"/>
      </geometry>
    </collision>
    <collision>
      <origin xyz="0.12 0.03 -0.03" rpy="0 0 0"/>
      <geometry>
        <sphere radius="0.005"/>
      </geometry>
    </collision>
    <collision>
      <origin xyz="0.12 -0.03 -0.03" rpy="0 0 0"/>
      <geometry>
        <sphere radius="0.005"/>
      </geometry>
    </collision>
  </link>
  <joint name="right_ankle_roll_joint" type="revolute">
    <origin xyz="0 0 -0.017558" rpy="0 0 0"/>
    <parent link="right_ankle_pitch_link"/>
    <child link="right_ankle_roll_link"/>
    <axis xyz="1 0 0"/>
    <limit lower="-0.2618" upper="0.2618" effort="35" velocity="30"/>
  </joint>


  <link name="waist_yaw_link">
    <inertial>
      <origin xyz="0.003494 0.000233 0.018034" rpy="0 0 0"/>
      <mass value="0.214"/>
      <inertia ixx="0.00010673" ixy="2.703E-06" ixz="-7.631E-06" iyy="0.00010422" iyz="-2.01E-07" izz="0.0001625"/>
    </inertial>
    <visual>
      <origin xyz="0 0 0" rpy="0 0 0"/>
      <geometry>
        <mesh filename="meshes/waist_yaw_link_rev_1_0.STL"/>
      </geometry>
      <material name="white"/>
    </visual>
  </link>
  <joint name="waist_yaw_joint" type="revolute">
    <origin xyz="0 0 0" rpy="0 0 0"/>
    <parent link="pelvis"/>
    <child link="waist_yaw_link"/>
    <axis xyz="0 0 1"/>
    <limit lower="-2.618" upper="2.618" effort="88" velocity="32"/>
  </joint>
  <link name="waist_roll_link">
    <inertial>
      <origin xyz="0 2.3E-05 0" rpy="0 0 0"/>
      <mass value="0.086"/>
      <inertia ixx="7.079E-06" ixy="0" ixz="0" iyy="6.339E-06" iyz="0" izz="8.245E-06"/>
    </inertial>
    <visual>
      <origin xyz="0 0 0" rpy="0 0 0"/>
      <geometry>
        <mesh filename="meshes/waist_roll_link_rev_1_0.STL"/>
      </geometry>
      <material name="white"/>
    </visual>
  </link>
  <joint name="waist_roll_joint" type="revolute">
    <origin xyz="-0.0039635 0 0.044" rpy="0 0 0"/>
    <parent link="waist_yaw_link"/>
    <child link="waist_roll_link"/>
    <axis xyz="1 0 0"/>
    <limit lower="-0.52" upper="0.52" effort="35" velocity="30"/>
  </joint>
  <link name="torso_link">
    <inertial>
      <origin xyz="0.000931 0.000346 0.15082" rpy="0 0 0"/>
      <mass value="6.78"/>
      <inertia ixx="0.05905" ixy="3.3302E-05" ixz="-0.0017715" iyy="0.047014" iyz="-2.2399E-05" izz="0.025652"/>
    </inertial>
    <visual>
      <origin xyz="0 0 0" rpy="0 0 0"/>
      <geometry>
        <mesh filename="meshes/torso_link_rev_1_0.STL"/>
      </geometry>
      <material name="white"/>
    </visual>
    <collision>
      <origin xyz="0 0 0" rpy="0 0 0"/>
      <geometry>
        <mesh filename="meshes/torso_link_rev_1_0.STL"/>
      </geometry>
    </collision>
  </link>
  <joint name="waist_pitch_joint" type="revolute">
    <origin xyz="0 0 0" rpy="0 0 0"/>
    <parent link="waist_roll_link"/>
    <child link="torso_link"/>
    <axis xyz="0 1 0"/>
    <limit lower="-0.52" upper="0.52" effort="35" velocity="30"/>
  </joint>


  <joint name="logo_joint" type="fixed">
    <origin xyz="0.0039635 0 -0.044" rpy="0 0 0"/>
    <parent link="torso_link"/>
    <child link="logo_link"/>
  </joint>
  <link name="logo_link">
    <inertial>
      <origin xyz="0 0 0" rpy="0 0 0"/>
      <mass value="0.001"/>
      <inertia ixx="1e-7" ixy="0" ixz="0" iyy="1e-7" iyz="0" izz="1e-7"/>
    </inertial>
    <visual>
      <origin xyz="0 0 0" rpy="0 0 0"/>
      <geometry>
        <mesh filename="meshes/logo_link.STL"/>
      </geometry>
      <material name="dark"/>
    </visual>
    <collision>
      <origin xyz="0 0 0" rpy="0 0 0"/>
      <geometry>
        <mesh filename="meshes/logo_link.STL"/>
      </geometry>
    </collision>
  </link>


  <link name="head_link">
    <inertial>
      <origin xyz="0.005267 0.000299 0.449869" rpy="0 0 0"/>
      <mass value="1.036"/>
      <inertia ixx="0.004085051" ixy="-2.543E-06" ixz="-6.9455E-05" iyy="0.004185212" iyz="-3.726E-06" izz="0.001807911"/>
    </inertial>
    <visual>
      <origin xyz="0 0 0" rpy="0 0 0"/>
      <geometry>
        <mesh filename="meshes/head_link.STL"/>
      </geometry>
      <material name="dark"/>
    </visual>
    <collision>
      <origin xyz="0 0 0" rpy="0 0 0"/>
      <geometry>
        <mesh filename="meshes/head_link.STL"/>
      </geometry>
    </collision>
  </link>
  <joint name="head_joint" type="fixed">
    <origin xyz="0.0039635 0 -0.044" rpy="0 0 0"/>
    <parent link="torso_link"/>
    <child link="head_link"/>
  </joint>


  <link name="imu_in_torso"/>
  <joint name="imu_in_torso_joint" type="fixed">
    <origin xyz="-0.03959 -0.00224 0.14792" rpy="0 0 0"/>
    <parent link="torso_link"/>
    <child link="imu_in_torso"/>
  </joint>

  <link name="imu_in_pelvis"/>
  <joint name="imu_in_pelvis_joint" type="fixed">
    <origin xyz="0.04525 0 -0.08339" rpy="0 0 0"/>
    <parent link="pelvis"/>
    <child link="imu_in_pelvis"/>
  </joint>


  <link name="d435_link"/>
  <joint name="d435_joint" type="fixed">
    <origin xyz="0.0576235 0.01753 0.42987" rpy="0 0.8307767239493009 0"/>
    <parent link="torso_link"/>
    <child link="d435_link"/>
  </joint>


  <link name="mid360_link"/>
  <joint name="mid360_joint" type="fixed">
    <origin xyz="0.0002835 0.00003 0.41618" rpy="0 0.04014257279586953 0"/>
    <parent link="torso_link"/>
    <child link="mid360_link"/>
  </joint>


  <link name="left_shoulder_pitch_link">
    <inertial>
      <origin xyz="0 0.035892 -0.011628" rpy="0 0 0"/>
      <mass value="0.718"/>
      <inertia ixx="0.0004291" ixy="-9.2E-06" ixz="6.4E-06" iyy="0.000453" iyz="2.26E-05" izz="0.000423"/>
    </inertial>
    <visual>
      <origin xyz="0 0 0" rpy="0 0 0"/>
      <geometry>
        <mesh filename="meshes/left_shoulder_pitch_link.STL"/>
      </geometry>
      <material name="white"/>
    </visual>
    <collision>
      <origin xyz="0 0.04 -0.01" rpy="0 1.5707963267948966 0"/>
      <geometry>
        <cylinder radius="0.03" length="0.05"/>
      </geometry>
    </collision>
  </link>
  <joint name="left_shoulder_pitch_joint" type="revolute">
    <origin xyz="0.0039563 0.10022 0.24778" rpy="0.27931 5.4949E-05 -0.00019159"/>
    <parent link="torso_link"/>
    <child link="left_shoulder_pitch_link"/>
    <axis xyz="0 1 0"/>
    <limit lower="-3.0892" upper="2.6704" effort="25" velocity="37"/>
  </joint>
  <link name="left_shoulder_roll_link">
    <inertial>
      <origin xyz="-0.000227 0.00727 -0.063243" rpy="0 0 0"/>
      <mass value="0.643"/>
      <inertia ixx="0.0006177" ixy="-1E-06" ixz="8.7E-06" iyy="0.0006912" iyz="-5.3E-06" izz="0.0003894"/>
    </inertial>
    <visual>
      <origin xyz="0 0 0" rpy="0 0 0"/>
      <geometry>
        <mesh filename="meshes/left_shoulder_roll_link.STL"/>
      </geometry>
      <material name="white"/>
    </visual>
    <collision>
      <origin xyz="-0.004 0.006 -0.053" rpy="0 0 0"/>
      <geometry>
        <cylinder radius="0.03" length="0.03"/>
      </geometry>
    </collision>
  </link>
  <joint name="left_shoulder_roll_joint" type="revolute">
    <origin xyz="0 0.038 -0.013831" rpy="-0.27925 0 0"/>
    <parent link="left_shoulder_pitch_link"/>
    <child link="left_shoulder_roll_link"/>
    <axis xyz="1 0 0"/>
    <limit lower="-1.5882" upper="2.2515" effort="25" velocity="37"/>
  </joint>
  <link name="left_shoulder_yaw_link">
    <inertial>
      <origin xyz="0.010773 -0.002949 -0.072009" rpy="0 0 0"/>
      <mass value="0.734"/>
      <inertia ixx="0.0009988" ixy="7.9E-06" ixz="0.0001412" iyy="0.0010605" iyz="-2.86E-05" izz="0.0004354"/>
    </inertial>
    <visual>
      <origin xyz="0 0 0" rpy="0 0 0"/>
      <geometry>
        <mesh filename="meshes/left_shoulder_yaw_link.STL"/>
      </geometry>
      <material name="white"/>
    </visual>
    <collision>
      <origin xyz="0 0 0" rpy="0 0 0"/>
      <geometry>
        <mesh filename="meshes/left_shoulder_yaw_link.STL"/>
      </geometry>
    </collision>
  </link>
  <joint name="left_shoulder_yaw_joint" type="revolute">
    <origin xyz="0 0.00624 -0.1032" rpy="0 0 0"/>
    <parent link="left_shoulder_roll_link"/>
    <child link="left_shoulder_yaw_link"/>
    <axis xyz="0 0 1"/>
    <limit lower="-2.618" upper="2.618" effort="25" velocity="37"/>
  </joint>
  <link name="left_elbow_link">
    <inertial>
      <origin xyz="0.064956 0.004454 -0.010062" rpy="0 0 0"/>
      <mass value="0.6"/>
      <inertia ixx="0.0002891" ixy="6.53E-05" ixz="1.72E-05" iyy="0.0004152" iyz="-5.6E-06" izz="0.0004197"/>
    </inertial>
    <visual>
      <origin xyz="0 0 0" rpy="0 0 0"/>
      <geometry>
        <mesh filename="meshes/left_elbow_link.STL"/>
      </geometry>
      <material name="white"/>
    </visual>
    <collision>
      <origin xyz="0 0 0" rpy="0 0 0"/>
      <geometry>
        <mesh filename="meshes/left_elbow_link.STL"/>
      </geometry>
    </collision>
  </link>
  <joint name="left_elbow_joint" type="revolute">
    <origin xyz="0.015783 0 -0.080518" rpy="0 0 0"/>
    <parent link="left_shoulder_yaw_link"/>
    <child link="left_elbow_link"/>
    <axis xyz="0 1 0"/>
    <limit lower="-1.0472" upper="2.0944" effort="25" velocity="37"/>
  </joint>
  <joint name="left_wrist_roll_joint" type="revolute">
    <origin xyz="0.100 0.00188791 -0.010" rpy="0 0 0"/>
    <axis xyz="1 0 0"/>
    <parent link="left_elbow_link"/>
    <child link="left_wrist_roll_link"/>
    <limit effort="25" velocity="37" lower="-1.972222054" upper="1.972222054"/>
  </joint>
  <link name="left_wrist_roll_link">
    <inertial>
      <origin xyz="0.01713944778 0.00053759094 0.00000048864" rpy="0 0 0"/>
      <mass value="0.08544498"/>
      <inertia ixx="0.00004821544023" ixy="-0.00000424511021" ixz="0.00000000510599" iyy="0.00003722899093" iyz="-0.00000000123525" izz="0.00005482106541"/>
    </inertial>
    <visual>
      <origin xyz="0 0 0" rpy="0 0 0"/>
      <geometry>
        <mesh filename="meshes/left_wrist_roll_link.STL"/>
      </geometry>
      <material name="white"/>
    </visual>
    <collision>
      <origin xyz="0 0 0" rpy="0 0 0"/>
      <geometry>
        <mesh filename="meshes/left_wrist_roll_link.STL"/>
      </geometry>
    </collision>
  </link>
  <joint name="left_wrist_pitch_joint" type="revolute">
    <origin xyz="0.038 0 0" rpy="0 0 0"/>
    <axis xyz="0 1 0"/>
    <parent link="left_wrist_roll_link"/>
    <child link="left_wrist_pitch_link"/>
    <limit effort="5" velocity="22" lower="-1.614429558" upper="1.614429558"/>
  </joint>
  <link name="left_wrist_pitch_link">
    <inertial>
      <origin xyz="0.02299989837 -0.00111685314 -0.00111658096" rpy="0 0 0"/>
      <mass value="0.48404956"/>
      <inertia ixx="0.00016579646273" ixy="-0.00001231206746" ixz="0.00001231699194" iyy="0.00042954057410" iyz="0.00000081417712" izz="0.00042953697654"/>
    </inertial>
    <visual>
      <origin xyz="0 0 0" rpy="0 0 0"/>
      <geometry>
        <mesh filename="meshes/left_wrist_pitch_link.STL"/>
      </geometry>
      <material name="white"/>
    </visual>
    <collision>
      <origin xyz="0 0 0" rpy="0 0 0"/>
      <geometry>
        <mesh filename="meshes/left_wrist_pitch_link.STL"/>
      </geometry>
    </collision>
  </link>
  <joint name="left_wrist_yaw_joint" type="revolute">
    <origin xyz="0.046 0 0" rpy="0 0 0"/>
    <axis xyz="0 0 1"/>
    <parent link="left_wrist_pitch_link"/>
    <child link="left_wrist_yaw_link"/>
    <limit effort="5" velocity="22" lower="-1.614429558" upper="1.614429558"/>
  </joint>
  <link name="left_wrist_yaw_link">
    <inertial>
      <origin xyz="0.02200381568 0.00049485096 0.00053861123" rpy="0 0 0"/>
      <mass value="0.08457647"/>
      <inertia ixx="0.00004929128828" ixy="-0.00000045735494" ixz="0.00000445867591" iyy="0.00005973338134" iyz="0.00000043217198" izz="0.00003928083826"/>
    </inertial>
    <visual>
      <origin xyz="0 0 0" rpy="0 0 0"/>
      <geometry>
        <mesh filename="meshes/left_wrist_yaw_link.STL"/>
      </geometry>
      <material name="white"/>
    </visual>
    <collision>
      <origin xyz="0 0 0" rpy="0 0 0"/>
      <geometry>
        <mesh filename="meshes/left_wrist_yaw_link.STL"/>
      </geometry>
    </collision>
  </link>
  <link name="right_shoulder_pitch_link">
    <inertial>
      <origin xyz="0 -0.035892 -0.011628" rpy="0 0 0"/>
      <mass value="0.718"/>
      <inertia ixx="0.0004291" ixy="9.2E-06" ixz="6.4E-06" iyy="0.000453" iyz="-2.26E-05" izz="0.000423"/>
    </inertial>
    <visual>
      <origin xyz="0 0 0" rpy="0 0 0"/>
      <geometry>
        <mesh filename="meshes/right_shoulder_pitch_link.STL"/>
      </geometry>
      <material name="white"/>
    </visual>
    <collision>
      <origin xyz="0 -0.04 -0.01" rpy="0 1.5707963267948966 0"/>
      <geometry>
        <cylinder radius="0.03" length="0.05"/>
      </geometry>
    </collision>
  </link>
  <joint name="right_shoulder_pitch_joint" type="revolute">
    <origin xyz="0.0039563 -0.10021 0.24778" rpy="-0.27931 5.4949E-05 0.00019159"/>
    <parent link="torso_link"/>
    <child link="right_shoulder_pitch_link"/>
    <axis xyz="0 1 0"/>
    <limit lower="-3.0892" upper="2.6704" effort="25" velocity="37"/>
  </joint>
  <link name="right_shoulder_roll_link">
    <inertial>
      <origin xyz="-0.000227 -0.00727 -0.063243" rpy="0 0 0"/>
      <mass value="0.643"/>
      <inertia ixx="0.0006177" ixy="1E-06" ixz="8.7E-06" iyy="0.0006912" iyz="5.3E-06" izz="0.0003894"/>
    </inertial>
    <visual>
      <origin xyz="0 0 0" rpy="0 0 0"/>
      <geometry>
        <mesh filename="meshes/right_shoulder_roll_link.STL"/>
      </geometry>
      <material name="white"/>
    </visual>
    <collision>
      <origin xyz="-0.004 -0.006 -0.053" rpy="0 0 0"/>
      <geometry>
        <cylinder radius="0.03" length="0.03"/>
      </geometry>
    </collision>
  </link>
  <joint name="right_shoulder_roll_joint" type="revolute">
    <origin xyz="0 -0.038 -0.013831" rpy="0.27925 0 0"/>
    <parent link="right_shoulder_pitch_link"/>
    <child link="right_shoulder_roll_link"/>
    <axis xyz="1 0 0"/>
    <limit lower="-2.2515" upper="1.5882" effort="25" velocity="37"/>
  </joint>
  <link name="right_shoulder_yaw_link">
    <inertial>
      <origin xyz="0.010773 0.002949 -0.072009" rpy="0 0 0"/>
      <mass value="0.734"/>
      <inertia ixx="0.0009988" ixy="-7.9E-06" ixz="0.0001412" iyy="0.0010605" iyz="2.86E-05" izz="0.0004354"/>
    </inertial>
    <visual>
      <origin xyz="0 0 0" rpy="0 0 0"/>
      <geometry>
        <mesh filename="meshes/right_shoulder_yaw_link.STL"/>
      </geometry>
      <material name="white"/>
    </visual>
    <collision>
      <origin xyz="0 0 0" rpy="0 0 0"/>
      <geometry>
        <mesh filename="meshes/right_shoulder_yaw_link.STL"/>
      </geometry>
    </collision>
  </link>
  <joint name="right_shoulder_yaw_joint" type="revolute">
    <origin xyz="0 -0.00624 -0.1032" rpy="0 0 0"/>
    <parent link="right_shoulder_roll_link"/>
    <child link="right_shoulder_yaw_link"/>
    <axis xyz="0 0 1"/>
    <limit lower="-2.618" upper="2.618" effort="25" velocity="37"/>
  </joint>
  <link name="right_elbow_link">
    <inertial>
      <origin xyz="0.064956 -0.004454 -0.010062" rpy="0 0 0"/>
      <mass value="0.6"/>
      <inertia ixx="0.0002891" ixy="-6.53E-05" ixz="1.72E-05" iyy="0.0004152" iyz="5.6E-06" izz="0.0004197"/>
    </inertial>
    <visual>
      <origin xyz="0 0 0" rpy="0 0 0"/>
      <geometry>
        <mesh filename="meshes/right_elbow_link.STL"/>
      </geometry>
      <material name="white"/>
    </visual>
    <collision>
      <origin xyz="0 0 0" rpy="0 0 0"/>
      <geometry>
        <mesh filename="meshes/right_elbow_link.STL"/>
      </geometry>
    </collision>
  </link>
  <joint name="right_elbow_joint" type="revolute">
    <origin xyz="0.015783 0 -0.080518" rpy="0 0 0"/>
    <parent link="right_shoulder_yaw_link"/>
    <child link="right_elbow_link"/>
    <axis xyz="0 1 0"/>
    <limit lower="-1.0472" upper="2.0944" effort="25" velocity="37"/>
  </joint>
  <joint name="right_wrist_roll_joint" type="revolute">
    <origin xyz="0.100 -0.00188791 -0.010" rpy="0 0 0"/>
    <axis xyz="1 0 0"/>
    <parent link="right_elbow_link"/>
    <child link="right_wrist_roll_link"/>
    <limit effort="25" velocity="37" lower="-1.972222054" upper="1.972222054"/>
  </joint>
  <link name="right_wrist_roll_link">
    <inertial>
      <origin xyz="0.01713944778 -0.00053759094 0.00000048864" rpy="0 0 0"/>
      <mass value="0.08544498"/>
      <inertia ixx="0.00004821544023" ixy="0.00000424511021" ixz="0.00000000510599" iyy="0.00003722899093" iyz="0.00000000123525" izz="0.00005482106541"/>
    </inertial>
    <visual>
      <origin xyz="0 0 0" rpy="0 0 0"/>
      <geometry>
        <mesh filename="meshes/right_wrist_roll_link.STL"/>
      </geometry>
      <material name="white"/>
    </visual>
    <collision>
      <origin xyz="0 0 0" rpy="0 0 0"/>
      <geometry>
        <mesh filename="meshes/right_wrist_roll_link.STL"/>
      </geometry>
    </collision>
  </link>
  <joint name="right_wrist_pitch_joint" type="revolute">
    <origin xyz="0.038 0 0" rpy="0 0 0"/>
    <axis xyz="0 1 0"/>
    <parent link="right_wrist_roll_link"/>
    <child link="right_wrist_pitch_link"/>
    <limit effort="5" velocity="22" lower="-1.614429558" upper="1.614429558"/>
  </joint>
  <link name="right_wrist_pitch_link">
    <inertial>
      <origin xyz="0.02299989837 0.00111685314 -0.00111658096" rpy="0 0 0"/>
      <mass value="0.48404956"/>
      <inertia ixx="0.00016579646273" ixy="0.00001231206746" ixz="0.00001231699194" iyy="0.00042954057410" iyz="-0.00000081417712" izz="0.00042953697654"/>
    </inertial>
    <visual>
      <origin xyz="0 0 0" rpy="0 0 0"/>
      <geometry>
        <mesh filename="meshes/right_wrist_pitch_link.STL"/>
      </geometry>
      <material name="white"/>
    </visual>
    <collision>
      <origin xyz="0 0 0" rpy="0 0 0"/>
      <geometry>
        <mesh filename="meshes/right_wrist_pitch_link.STL"/>
      </geometry>
    </collision>
  </link>
  <joint name="right_wrist_yaw_joint" type="revolute">
    <origin xyz="0.046 0 0" rpy="0 0 0"/>
    <axis xyz="0 0 1"/>
    <parent link="right_wrist_pitch_link"/>
    <child link="right_wrist_yaw_link"/>
    <limit effort="5" velocity="22" lower="-1.614429558" upper="1.614429558"/>
  </joint>
  <link name="right_wrist_yaw_link">
    <inertial>
      <origin xyz="0.02200381568 -0.00049485096 0.00053861123" rpy="0 0 0"/>
      <mass value="0.08457647"/>
      <inertia ixx="0.00004929128828" ixy="0.00000045735494" ixz="0.00000445867591" iyy="0.00005973338134" iyz="-0.00000043217198" izz="0.00003928083826"/>
    </inertial>
    <visual>
      <origin xyz="0 0 0" rpy="0 0 0"/>
      <geometry>
        <mesh filename="meshes/right_wrist_yaw_link.STL"/>
      </geometry>
      <material name="white"/>
    </visual>
    <collision>
      <origin xyz="0 0 0" rpy="0 0 0"/>
      <geometry>
        <mesh filename="meshes/right_wrist_yaw_link.STL"/>
      </geometry>
    </collision>
  </link>
  <joint name="L_base_link_joint" type="fixed">
    <origin xyz="0.0415 0 0" rpy="0 0 1.5707963267948966192313216916398"/>
    <parent link="left_wrist_yaw_link"/>
    <child link="L_hand_base_link"/>
  </joint>

  <link name="L_hand_base_link">
    <inertial>
      <origin xyz="-0.002551 -0.066047 -0.0019357" rpy="0 0 0"/>
      <mass value="0.14143"/>
      <inertia ixx="0.0001234" ixy="2.1995E-06" ixz="-1.7694E-06" iyy="8.3835E-05" iyz="1.5968E-06" izz="7.7231E-05"/>
    </inertial>
    <visual>
      <origin xyz="0 0 0" rpy="0 0 0"/>
      <geometry>
        <mesh filename="meshes/L_hand_base_link.STL"/>
      </geometry>
      <material name="dark">
        <color rgba="1 1 1 1"/>
      </material>
    </visual>
    <collision>
      <origin xyz="0 0 0" rpy="0 0 0"/>
      <geometry>
        <mesh filename="meshes/L_hand_base_link.STL"/>
      </geometry>
    </collision>
  </link>

  <link name="L_thumb_proximal_base">
    <inertial>
      <origin xyz="0.0048817 0.00038782 -0.00722" rpy="0 0 0"/>
      <mass value="0.0018869"/>
      <inertia ixx="5.5158E-08" ixy="-1.1803E-08" ixz="-4.6743E-09" iyy="8.2164E-08" iyz="-1.3521E-09" izz="6.7434E-08"/>
    </inertial>
    <visual>
      <origin xyz="0 0 0" rpy="0 0 0"/>
      <geometry>
        <mesh filename="meshes/Link11_L.STL"/>
      </geometry>
      <material name="dark">
        <color rgba="1 1 1 1"/>
      </material>
    </visual>
    <collision>
      <origin xyz="0 0 0" rpy="0 0 0"/>
      <geometry>
        <mesh filename="meshes/Link11_L.STL"/>
      </geometry>
    </collision>
  </link>

  <joint name="L_thumb_proximal_yaw_joint" type="revolute">
    <origin xyz="-0.01696 -0.0691 0.02045" rpy="1.5708 -1.5708 0"/>
    <parent link="L_hand_base_link"/>
    <child link="L_thumb_proximal_base"/>
    <axis xyz="0 0 1"/>
    <limit lower="-0.1" upper="1.3" effort="1" velocity="0.5"/>
  </joint>

  <link name="L_thumb_proximal">
    <inertial>
      <origin xyz="0.021936 -0.01279 -0.0080386" rpy="0 0 0"/>
      <mass value="0.0066101"/>
      <inertia ixx="1.5693E-06" ixy="7.8339E-07" ixz="8.5959E-10" iyy="1.7356E-06" iyz="1.0378E-09" izz="2.787E-06"/>
    </inertial>
    <visual>
      <origin xyz="0 0 0" rpy="0 0 0"/>
      <geometry>
        <mesh filename="meshes/Link12_L.STL"/>
      </geometry>
      <material name="dark">
        <color rgba="1 1 1 1"/>
      </material>
    </visual>
    <collision>
      <origin xyz="0 0 0" rpy="0 0 0"/>
      <geometry>
        <mesh filename="meshes/Link12_L.STL"/>
      </geometry>
    </collision>
  </link>

  <joint name="L_thumb_proximal_pitch_joint" type="revolute">
    <origin xyz="0.0099867 0.0098242 -0.0089" rpy="-1.5708 0 0.16939"/>
    <parent link="L_thumb_proximal_base"/>
    <child link="L_thumb_proximal"/>
    <axis xyz="0 0 -1"/>
    <limit lower="-0.1" upper="0.6" effort="1" velocity="0.5"/>
  </joint>

  <link name="L_thumb_intermediate">
    <inertial>
      <origin xyz="0.0095531 0.0016282 -0.0072002" rpy="0 0 0"/>
      <mass value="0.0037844"/>
      <inertia ixx="3.6981E-07" ixy="9.8603E-08" ixz="-2.8173E-12" iyy="3.2395E-07" iyz="-2.8028E-12" izz="4.6532E-07"/>
    </inertial>
    <visual>
      <origin xyz="0 0 0" rpy="0 0 0"/>
      <geometry>
        <mesh filename="meshes/Link13_L.STL"/>
      </geometry>
      <material name="dark">
        <color rgba="1 1 1 1"/>
      </material>
    </visual>
    <collision>
      <origin xyz="0 0 0" rpy="0 0 0"/>
      <geometry>
        <mesh filename="meshes/Link13_L.STL"/>
      </geometry>
    </collision>
  </link>

  <joint name="L_thumb_intermediate_joint" type="revolute">
    <origin xyz="0.04407 -0.034553 -0.0008" rpy="0 0 0"/>
    <parent link="L_thumb_proximal"/>
    <child link="L_thumb_intermediate"/>
    <axis xyz="0 0 -1"/>
    <limit lower="0" upper="0.8" effort="1" velocity="0.5"/>
    <mimic joint="L_thumb_proximal_pitch_joint" multiplier="1.6" offset="0"/>
  </joint>

  <link name="L_thumb_distal">
    <inertial>
      <origin xyz="0.0092888 -0.004953 -0.0060033" rpy="0 0 0"/>
      <mass value="0.003344"/>
      <inertia ixx="1.3632E-07" ixy="5.6787E-08" ixz="-9.1939E-11" iyy="1.4052E-07" iyz="1.2145E-10" izz="2.0026E-07"/>
    </inertial>
    <visual>
      <origin xyz="0 0 0" rpy="0 0 0"/>
      <geometry>
        <mesh filename="meshes/Link14_L.STL"/>
      </geometry>
      <material name="dark">
        <color rgba="1 1 1 1"/>
      </material>
    </visual>
    <collision>
      <origin xyz="0 0 0" rpy="0 0 0"/>
      <geometry>
        <mesh filename="meshes/Link14_L.STL"/>
      </geometry>
    </collision>
  </link>

  <joint name="L_thumb_distal_joint" type="revolute">
    <origin xyz="0.020248 -0.010156 -0.0012" rpy="0 0 0"/>
    <parent link="L_thumb_intermediate"/>
    <child link="L_thumb_distal"/>
    <axis xyz="0 0 -1"/>
    <limit lower="0" upper="1.2" effort="1" velocity="0.5"/>
    <mimic joint="L_thumb_proximal_pitch_joint" multiplier="2.4" offset="0"/>
  </joint>

  <link name="L_index_proximal">
    <inertial>
      <origin xyz="0.0012971 -0.011934 -0.0059998" rpy="0 0 0"/>
      <mass value="0.0042405"/>
      <inertia ixx="6.6215E-07" ixy="1.8442E-08" ixz="1.3746E-12" iyy="2.1167E-07" iyz="-1.4773E-11" izz="6.9402E-07"/>
    </inertial>
    <visual>
      <origin xyz="0 0 0" rpy="0 0 0"/>
      <geometry>
        <mesh filename="meshes/Link15_L.STL"/>
      </geometry>
      <material name="dark">
        <color rgba="1 1 1 1"/>
      </material>
    </visual>
    <collision>
      <origin xyz="0 0 0" rpy="0 0 0"/>
      <geometry>
        <mesh filename="meshes/Link15_L.STL"/>
      </geometry>
    </collision>
  </link>

  <joint name="L_index_proximal_joint" type="revolute">
    <origin xyz="0.00028533 -0.13653 0.032268" rpy="-0.034907 0 0"/>
    <parent link="L_hand_base_link"/>
    <child link="L_index_proximal"/>
    <axis xyz="0 0 -1"/>
    <limit lower="0" upper="1.7" effort="1" velocity="0.5"/>
  </joint>

  <link name="L_index_intermediate">
    <inertial>
      <origin xyz="0.0021753 -0.019567 -0.005" rpy="0 0 0"/>
      <mass value="0.0045682"/>
      <inertia ixx="7.6284E-07" ixy="-8.063E-08" ixz="3.6797E-13" iyy="9.4308E-08" iyz="1.5743E-13" izz="7.8176E-07"/>
    </inertial>
    <visual>
      <origin xyz="0 0 0" rpy="0 0 0"/>
      <geometry>
        <mesh filename="meshes/Link16_L.STL"/>
      </geometry>
      <material name="dark">
        <color rgba="1 1 1 1"/>
      </material>
    </visual>
    <collision>
      <origin xyz="0 0 0" rpy="0 0 0"/>
      <geometry>
        <mesh filename="meshes/Link16_L.STL"/>
      </geometry>
    </collision>
  </link>

  <joint name="L_index_intermediate_joint" type="revolute">
    <origin xyz="-0.0024229 -0.032041 -0.001" rpy="0 0 0"/>
    <parent link="L_index_proximal"/>
    <child link="L_index_intermediate"/>
    <axis xyz="0 0 -1"/>
    <limit lower="0" upper="1.7" effort="1" velocity="0.5"/>
    <mimic joint="L_index_proximal_joint" multiplier="1" offset="0"/>
  </joint>

  <link name="L_middle_proximal">
    <inertial>
      <origin xyz="0.0012971 -0.011934 -0.0059999" rpy="0 0 0"/>
      <mass value="0.0042405"/>
      <inertia ixx="6.6215E-07" ixy="1.8442E-08" ixz="1.2299E-12" iyy="2.1167E-07" iyz="-1.4484E-11" izz="6.9402E-07"/>
    </inertial>
    <visual>
      <origin xyz="0 0 0" rpy="0 0 0"/>
      <geometry>
        <mesh filename="meshes/Link17_L.STL"/>
      </geometry>
      <material name="dark">
        <color rgba="1 1 1 1"/>
      </material>
    </visual>
    <collision>
      <origin xyz="0 0 0" rpy="0 0 0"/>
      <geometry>
        <mesh filename="meshes/Link17_L.STL"/>
      </geometry>
    </collision>
  </link>

  <joint name="L_middle_proximal_joint" type="revolute">
    <origin xyz="0.00028533 -0.1371 0.01295" rpy="0 0 0"/>
    <parent link="L_hand_base_link"/>
    <child link="L_middle_proximal"/>
    <axis xyz="0 0 -1"/>
    <limit lower="0" upper="1.7" effort="1" velocity="0.5"/>
  </joint>

  <link name="L_middle_intermediate">
    <inertial>
      <origin xyz="0.001921 -0.020796 -0.0049999" rpy="0 0 0"/>
      <mass value="0.0050397"/>
      <inertia ixx="9.5823E-07" ixy="-1.1425E-07" ixz="-2.4186E-12" iyy="1.0646E-07" iyz="3.6974E-12" izz="9.8385E-07"/>
    </inertial>
    <visual>
      <origin xyz="0 0 0" rpy="0 0 0"/>
      <geometry>
        <mesh filename="meshes/Link18_L.STL"/>
      </geometry>
      <material name="dark">
        <color rgba="1 1 1 1"/>
      </material>
    </visual>
    <collision>
      <origin xyz="0 0 0" rpy="0 0 0"/>
      <geometry>
        <mesh filename="meshes/Link18_L.STL"/>
      </geometry>
    </collision>
  </link>

  <joint name="L_middle_intermediate_joint" type="revolute">
    <origin xyz="-0.0024229 -0.032041 -0.001" rpy="0 0 0"/>
    <parent link="L_middle_proximal"/>
    <child link="L_middle_intermediate"/>
    <axis xyz="0 0 -1"/>
    <limit lower="0" upper="1.7" effort="1" velocity="0.5"/>
    <mimic joint="L_middle_proximal_joint" multiplier="1" offset="0"/>
  </joint>

  <link name="L_ring_proximal">
    <inertial>
      <origin xyz="0.0012971 -0.011934 -0.0059999" rpy="0 0 0"/>
      <mass value="0.0042405"/>
      <inertia ixx="6.6215E-07" ixy="1.8442E-08" ixz="9.6052E-13" iyy="2.1167E-07" iyz="-1.4124E-11" izz="6.9402E-07"/>
    </inertial>
    <visual>
      <origin xyz="0 0 0" rpy="0 0 0"/>
      <geometry>
        <mesh filename="meshes/Link19_L.STL"/>
      </geometry>
      <material name="dark">
        <color rgba="1 1 1 1"/>
      </material>
    </visual>
    <collision>
      <origin xyz="0 0 0" rpy="0 0 0"/>
      <geometry>
        <mesh filename="meshes/Link19_L.STL"/>
      </geometry>
    </collision>
  </link>

  <joint name="L_ring_proximal_joint" type="revolute">
    <origin xyz="0.00028533 -0.13691 -0.0062872" rpy="0.05236 0 0"/>
    <parent link="L_hand_base_link"/>
    <child link="L_ring_proximal"/>
    <axis xyz="0 0 -1"/>
    <limit lower="0" upper="1.7" effort="1" velocity="0.5"/>
  </joint>

  <link name="L_ring_intermediate">
    <inertial>
      <origin xyz="0.0021753 -0.019567 -0.005" rpy="0 0 0"/>
      <mass value="0.0045682"/>
      <inertia ixx="7.6285E-07" ixy="-8.0631E-08" ixz="3.3472E-14" iyy="9.4308E-08" iyz="-4.4773E-13" izz="7.8176E-07"/>
    </inertial>
    <visual>
      <origin xyz="0 0 0" rpy="0 0 0"/>
      <geometry>
        <mesh filename="meshes/Link20_L.STL"/>
      </geometry>
      <material name="dark">
        <color rgba="1 1 1 1"/>
      </material>
    </visual>
    <collision>
      <origin xyz="0 0 0" rpy="0 0 0"/>
      <geometry>
        <mesh filename="meshes/Link20_L.STL"/>
      </geometry>
    </collision>
  </link>

  <joint name="L_ring_intermediate_joint" type="revolute">
    <origin xyz="-0.0024229 -0.032041 -0.001" rpy="0 0 0"/>
    <parent link="L_ring_proximal"/>
    <child link="L_ring_intermediate"/>
    <axis xyz="0 0 -1"/>
    <limit lower="0" upper="1.7" effort="1" velocity="0.5"/>
    <mimic joint="L_ring_proximal_joint" multiplier="1" offset="0"/>
  </joint>

  <link name="L_pinky_proximal">
    <inertial>
      <origin xyz="0.0012971 -0.011934 -0.0059999" rpy="0 0 0"/>
      <mass value="0.0042405"/>
      <inertia ixx="6.6215E-07" ixy="1.8442E-08" ixz="1.0279E-12" iyy="2.1167E-07" iyz="-1.4277E-11" izz="6.9402E-07"/>
    </inertial>
    <visual>
      <origin xyz="0 0 0" rpy="0 0 0"/>
      <geometry>
        <mesh filename="meshes/Link21_L.STL"/>
      </geometry>
      <material name="dark">
        <color rgba="1 1 1 1"/>
      </material>
    </visual>
    <collision>
      <origin xyz="0 0 0" rpy="0 0 0"/>
      <geometry>
        <mesh filename="meshes/Link21_L.STL"/>
      </geometry>
    </collision>
  </link>

  <joint name="L_pinky_proximal_joint" type="revolute">
    <origin xyz="0.00028533 -0.13571 -0.025488" rpy="0.10472 0 0"/>
    <parent link="L_hand_base_link"/>
    <child link="L_pinky_proximal"/>
    <axis xyz="0 0 -1"/>
    <limit lower="0" upper="1.7" effort="1" velocity="0.5"/>
  </joint>

  <link name="L_pinky_intermediate">
    <inertial>
      <origin xyz="0.0024788 -0.016208 -0.0050001" rpy="0 0 0"/>
      <mass value="0.0036036"/>
      <inertia ixx="4.3923E-07" ixy="-4.1355E-08" ixz="1.2263E-12" iyy="7.0315E-08" iyz="3.1311E-12" izz="4.4881E-07"/>
    </inertial>
    <visual>
      <origin xyz="0 0 0" rpy="0 0 0"/>
      <geometry>
        <mesh filename="meshes/Link22_L.STL"/>
      </geometry>
      <material name="dark">
        <color rgba="1 1 1 1"/>
      </material>
    </visual>
    <collision>
      <origin xyz="0 0 0" rpy="0 0 0"/>
      <geometry>
        <mesh filename="meshes/Link22_L.STL"/>
      </geometry>
    </collision>
  </link>

  <joint name="L_pinky_intermediate_joint" type="revolute">
    <origin xyz="-0.0024229 -0.032041 -0.001" rpy="0 0 0"/>
    <parent link="L_pinky_proximal"/>
    <child link="L_pinky_intermediate"/>
    <axis xyz="0 0 -1"/>
    <limit lower="0" upper="1.7" effort="1" velocity="0.5"/>
    <mimic joint="L_pinky_proximal_joint" multiplier="1" offset="0"/>
  </joint>

  <joint name="R_base_link_joint" type="fixed">
    <origin xyz="0.0415 0 0" rpy="3.1415926535897932384626433832795 0 -1.5707963267948966192313216916398"/>
    <parent link="right_wrist_yaw_link"/>
    <child link="R_hand_base_link"/>
  </joint>

  <link name="R_hand_base_link">
    <inertial>
      <origin xyz="-0.0025264 -0.066047 0.0019598" rpy="0 0 0"/>
      <mass value="0.14143"/>
      <inertia ixx="0.00012281" ixy="2.1711E-06" ixz="1.7709E-06" iyy="8.3832E-05" iyz="-1.6551E-06" izz="7.6663E-05"/>
    </inertial>
    <visual>
      <origin xyz="0 0 0" rpy="0 0 0"/>
      <geometry>
        <mesh filename="meshes/R_hand_base_link.STL"/>
      </geometry>
      <material name="dark">
        <color rgba="1 1 1 1"/>
      </material>
    </visual>
    <collision>
      <origin xyz="0 0 0" rpy="0 0 0"/>
      <geometry>
        <mesh filename="meshes/R_hand_base_link.STL"/>
      </geometry>
    </collision>
  </link>

  <link name="R_thumb_proximal_base">
    <inertial>
      <origin xyz="-0.0048064 0.0009382 -0.00757" rpy="0 0 0"/>
      <mass value="0.0018869"/>
      <inertia ixx="5.816E-08" ixy="1.4539E-08" ixz="4.491E-09" iyy="7.9161E-08" iyz="-1.8727E-09" izz="6.7433E-08"/>
    </inertial>
    <visual>
      <origin xyz="0 0 0" rpy="0 0 0"/>
      <geometry>
        <mesh filename="meshes/Link11_R.STL"/>
      </geometry>
      <material name="dark">
        <color rgba="1 1 1 1"/>
      </material>
    </visual>
    <collision>
      <origin xyz="0 0 0" rpy="0 0 0"/>
      <geometry>
        <mesh filename="meshes/Link11_R.STL"/>
      </geometry>
    </collision>
  </link>

  <joint name="R_thumb_proximal_yaw_joint" type="revolute">
    <origin xyz="-0.01696 -0.0691 -0.02045" rpy="1.5708 -1.5708 0"/>
    <parent link="R_hand_base_link"/>
    <child link="R_thumb_proximal_base"/>
    <axis xyz="0 0 -1"/>
    <limit lower="-0.1" upper="1.3" effort="1" velocity="0.5"/>
  </joint>

  <link name="R_thumb_proximal">
    <inertial>
      <origin xyz="0.021932 0.012785 -0.0080386" rpy="0 0 0"/>
      <mass value="0.0066075"/>
      <inertia ixx="1.5686E-06" ixy="-7.8296E-07" ixz="8.9143E-10" iyy="1.7353E-06" iyz="-1.0191E-09" izz="2.786E-06"/>
    </inertial>
    <visual>
      <origin xyz="0 0 0" rpy="0 0 0"/>
      <geometry>
        <mesh filename="meshes/Link12_R.STL"/>
      </geometry>
      <material name="dark">
        <color rgba="1 1 1 1"/>
      </material>
    </visual>
    <collision>
      <origin xyz="0 0 0" rpy="0 0 0"/>
      <geometry>
        <mesh filename="meshes/Link12_R.STL"/>
      </geometry>
    </collision>
  </link>

  <joint name="R_thumb_proximal_pitch_joint" type="revolute">
    <origin xyz="-0.0088099 0.010892 -0.00925" rpy="1.5708 0 2.8587"/>
    <parent link="R_thumb_proximal_base"/>
    <child link="R_thumb_proximal"/>
    <axis xyz="0 0 1"/>
    <limit lower="-0.1" upper="0.6" effort="1" velocity="0.5"/>
  </joint>

  <link name="R_thumb_intermediate">
    <inertial>
      <origin xyz="0.0095544 -0.0016282 -0.0071997" rpy="0 0 0"/>
      <mass value="0.0037847"/>
      <inertia ixx="3.6981E-07" ixy="-9.8581E-08" ixz="-4.7469E-12" iyy="3.2394E-07" iyz="1.0939E-12" izz="4.6531E-07"/>
    </inertial>
    <visual>
      <origin xyz="0 0 0" rpy="0 0 0"/>
      <geometry>
        <mesh filename="meshes/Link13_R.STL"/>
      </geometry>
      <material name="dark">
        <color rgba="1 1 1 1"/>
      </material>
    </visual>
    <collision>
      <origin xyz="0 0 0" rpy="0 0 0"/>
      <geometry>
        <mesh filename="meshes/Link13_R.STL"/>
      </geometry>
    </collision>
  </link>

  <joint name="R_thumb_intermediate_joint" type="revolute">
    <origin xyz="0.04407 0.034553 -0.0008" rpy="0 0 0"/>
    <parent link="R_thumb_proximal"/>
    <child link="R_thumb_intermediate"/>
    <axis xyz="0 0 1"/>
    <limit lower="0" upper="0.8" effort="1" velocity="0.5"/>
    <mimic joint="R_thumb_proximal_pitch_joint" multiplier="1.6" offset="0"/>
  </joint>

  <link name="R_thumb_distal">
    <inertial>
      <origin xyz="0.0092888 0.0049529 -0.0060033" rpy="0 0 0"/>
      <mass value="0.0033441"/>
      <inertia ixx="1.3632E-07" ixy="-5.6788E-08" ixz="-9.2764E-11" iyy="1.4052E-07" iyz="-1.2283E-10" izz="2.0026E-07"/>
    </inertial>
    <visual>
      <origin xyz="0 0 0" rpy="0 0 0"/>
      <geometry>
        <mesh filename="meshes/Link14_R.STL"/>
      </geometry>
      <material name="dark">
        <color rgba="1 1 1 1"/>
      </material>
    </visual>
    <collision>
      <origin xyz="0 0 0" rpy="0 0 0"/>
      <geometry>
        <mesh filename="meshes/Link14_R.STL"/>
      </geometry>
    </collision>
  </link>

  <joint name="R_thumb_distal_joint" type="revolute">
    <origin xyz="0.020248 0.010156 -0.0012" rpy="0 0 0"/>
    <parent link="R_thumb_intermediate"/>
    <child link="R_thumb_distal"/>
    <axis xyz="0 0 1"/>
    <limit lower="0" upper="1.2" effort="1" velocity="0.5"/>
    <mimic joint="R_thumb_proximal_pitch_joint" multiplier="2.4" offset="0"/>
  </joint>

  <link name="R_index_proximal">
    <inertial>
      <origin xyz="0.0012259 0.011942 -0.0060001" rpy="0 0 0"/>
      <mass value="0.0042403"/>
      <inertia ixx="6.6232E-07" ixy="-1.5775E-08" ixz="1.8515E-12" iyy="2.1146E-07" iyz="-5.0828E-12" izz="6.9398E-07"/>
    </inertial>
    <visual>
      <origin xyz="0 0 0" rpy="0 0 0"/>
      <geometry>
        <mesh filename="meshes/Link15_R.STL"/>
      </geometry>
      <material name="dark">
        <color rgba="1 1 1 1"/>
      </material>
    </visual>
    <collision>
      <origin xyz="0 0 0" rpy="0 0 0"/>
      <geometry>
        <mesh filename="meshes/Link15_R.STL"/>
      </geometry>
    </collision>
  </link>

  <joint name="R_index_proximal_joint" type="revolute">
    <origin xyz="0.00028533 -0.13653 -0.032268" rpy="-3.1067 0 0"/>
    <parent link="R_hand_base_link"/>
    <child link="R_index_proximal"/>
    <axis xyz="0 0 1"/>
    <limit lower="0" upper="1.7" effort="1" velocity="0.5"/>
  </joint>

  <link name="R_index_intermediate">
    <inertial>
      <origin xyz="0.0019697 0.019589 -0.005" rpy="0 0 0"/>
      <mass value="0.0045683"/>
      <inertia ixx="7.6111E-07" ixy="8.7637E-08" ixz="-3.7751E-13" iyy="9.6076E-08" iyz="9.9444E-13" izz="7.8179E-07"/>
    </inertial>
    <visual>
      <origin xyz="0 0 0" rpy="0 0 0"/>
      <geometry>
        <mesh filename="meshes/Link16_R.STL"/>
      </geometry>
      <material name="dark">
        <color rgba="1 1 1 1"/>
      </material>
    </visual>
    <collision>
      <origin xyz="0 0 0" rpy="0 0 0"/>
      <geometry>
        <mesh filename="meshes/Link16_R.STL"/>
      </geometry>
    </collision>
  </link>

  <joint name="R_index_intermediate_joint" type="revolute">
    <origin xyz="-0.0026138 0.032026 -0.001" rpy="0 0 0"/>
    <parent link="R_index_proximal"/>
    <child link="R_index_intermediate"/>
    <axis xyz="0 0 1"/>
    <limit lower="0" upper="1.7" effort="1" velocity="0.5"/>
    <mimic joint="R_index_proximal_joint" multiplier="1" offset="0"/>
  </joint>

  <link name="R_middle_proximal">
    <inertial>
      <origin xyz="0.001297 0.011934 -0.0060001" rpy="0 0 0"/>
      <mass value="0.0042403"/>
      <inertia ixx="6.6211E-07" ixy="-1.8461E-08" ixz="1.8002E-12" iyy="2.1167E-07" iyz="-6.6808E-12" izz="6.9397E-07"/>
    </inertial>
    <visual>
      <origin xyz="0 0 0" rpy="0 0 0"/>
      <geometry>
        <mesh filename="meshes/Link17_R.STL"/>
      </geometry>
      <material name="dark">
        <color rgba="1 1 1 1"/>
      </material>
    </visual>
    <collision>
      <origin xyz="0 0 0" rpy="0 0 0"/>
      <geometry>
        <mesh filename="meshes/Link17_R.STL"/>
      </geometry>
    </collision>
  </link>

  <joint name="R_middle_proximal_joint" type="revolute">
    <origin xyz="0.00028533 -0.1371 -0.01295" rpy="-3.1416 0 0"/>
    <parent link="R_hand_base_link"/>
    <child link="R_middle_proximal"/>
    <axis xyz="0 0 1"/>
    <limit lower="0" upper="1.7" effort="1" velocity="0.5"/>
  </joint>

  <link name="R_middle_intermediate">
    <inertial>
      <origin xyz="0.001921 0.020796 -0.005" rpy="0 0 0"/>
      <mass value="0.0050396"/>
      <inertia ixx="9.5822E-07" ixy="1.1425E-07" ixz="-2.4791E-12" iyy="1.0646E-07" iyz="5.9173E-12" izz="9.8384E-07"/>
    </inertial>
    <visual>
      <origin xyz="0 0 0" rpy="0 0 0"/>
      <geometry>
        <mesh filename="meshes/Link18_R.STL"/>
      </geometry>
      <material name="dark">
        <color rgba="1 1 1 1"/>
      </material>
    </visual>
    <collision>
      <origin xyz="0 0 0" rpy="0 0 0"/>
      <geometry>
        <mesh filename="meshes/Link18_R.STL"/>
      </geometry>
    </collision>
  </link>

  <joint name="R_middle_intermediate_joint" type="revolute">
    <origin xyz="-0.0024229 0.032041 -0.001" rpy="0 0 0"/>
    <parent link="R_middle_proximal"/>
    <child link="R_middle_intermediate"/>
    <axis xyz="0 0 1"/>
    <limit lower="0" upper="1.7" effort="1" velocity="0.5"/>
    <mimic joint="R_middle_proximal_joint" multiplier="1" offset="0"/>
  </joint>

  <link name="R_ring_proximal">
    <inertial>
      <origin xyz="0.001297 0.011934 -0.0060002" rpy="0 0 0"/>
      <mass value="0.0042403"/>
      <inertia ixx="6.6211E-07" ixy="-1.8461E-08" ixz="1.5793E-12" iyy="2.1167E-07" iyz="-6.6868E-12" izz="6.9397E-07"/>
    </inertial>
    <visual>
      <origin xyz="0 0 0" rpy="0 0 0"/>
      <geometry>
        <mesh filename="meshes/Link19_R.STL"/>
      </geometry>
      <material name="dark">
        <color rgba="1 1 1 1"/>
      </material>
    </visual>
    <collision>
      <origin xyz="0 0 0" rpy="0 0 0"/>
      <geometry>
        <mesh filename="meshes/Link19_R.STL"/>
      </geometry>
    </collision>
  </link>

  <joint name="R_ring_proximal_joint" type="revolute">
    <origin xyz="0.00028533 -0.13691 0.0062872" rpy="3.0892 0 0"/>
    <parent link="R_hand_base_link"/>
    <child link="R_ring_proximal"/>
    <axis xyz="0 0 1"/>
    <limit lower="0" upper="1.7" effort="1" velocity="0.5"/>
  </joint>

  <link name="R_ring_intermediate">
    <inertial>
      <origin xyz="0.0021753 0.019567 -0.005" rpy="0 0 0"/>
      <mass value="0.0045683"/>
      <inertia ixx="7.6286E-07" ixy="8.0635E-08" ixz="-6.1562E-13" iyy="9.431E-08" iyz="5.8619E-13" izz="7.8177E-07"/>
    </inertial>
    <visual>
      <origin xyz="0 0 0" rpy="0 0 0"/>
      <geometry>
        <mesh filename="meshes/Link20_R.STL"/>
      </geometry>
      <material name="dark">
        <color rgba="1 1 1 1"/>
      </material>
    </visual>
    <collision>
      <origin xyz="0 0 0" rpy="0 0 0"/>
      <geometry>
        <mesh filename="meshes/Link20_R.STL"/>
      </geometry>
    </collision>
  </link>

  <joint name="R_ring_intermediate_joint" type="revolute">
    <origin xyz="-0.0024229 0.032041 -0.001" rpy="0 0 0"/>
    <parent link="R_ring_proximal"/>
    <child link="R_ring_intermediate"/>
    <axis xyz="0 0 1"/>
    <limit lower="0" upper="1.7" effort="1" velocity="0.5"/>
    <mimic joint="R_ring_proximal_joint" multiplier="1" offset="0"/>
  </joint>

  <link name="R_pinky_proximal">
    <inertial>
      <origin xyz="0.001297 0.011934 -0.0060001" rpy="0 0 0"/>
      <mass value="0.0042403"/>
      <inertia ixx="6.6211E-07" ixy="-1.8461E-08" ixz="1.6907E-12" iyy="2.1167E-07" iyz="-6.9334E-12" izz="6.9397E-07"/>
    </inertial>
    <visual>
      <origin xyz="0 0 0" rpy="0 0 0"/>
      <geometry>
        <mesh filename="meshes/Link21_R.STL"/>
      </geometry>
      <material name="dark">
        <color rgba="1 1 1 1"/>
      </material>
    </visual>
    <collision>
      <origin xyz="0 0 0" rpy="0 0 0"/>
      <geometry>
        <mesh filename="meshes/Link21_R.STL"/>
      </geometry>
    </collision>
  </link>

  <joint name="R_pinky_proximal_joint" type="revolute">
    <origin xyz="0.00028533 -0.13571 0.025488" rpy="3.0369 0 0"/>
    <parent link="R_hand_base_link"/>
    <child link="R_pinky_proximal"/>
    <axis xyz="0 0 1"/>
    <limit lower="0" upper="1.7" effort="1" velocity="0.5"/>
  </joint>

  <link name="R_pinky_intermediate">
    <inertial>
      <origin xyz="0.0024748 0.016203 -0.0050031" rpy="0 0 0"/>
      <mass value="0.0035996"/>
      <inertia ixx="4.3913E-07" ixy="4.1418E-08" ixz="3.7168E-11" iyy="7.0247E-08" iyz="5.8613E-11" izz="4.4867E-07"/>
    </inertial>
    <visual>
      <origin xyz="0 0 0" rpy="0 0 0"/>
      <geometry>
        <mesh filename="meshes/Link22_R.STL"/>
      </geometry>
      <material name="dark">
        <color rgba="1 1 1 1"/>
      </material>
    </visual>
    <collision>
      <origin xyz="0 0 0" rpy="0 0 0"/>
      <geometry>
        <mesh filename="meshes/Link22_R.STL"/>
      </geometry>
    </collision>
  </link>

  <joint name="R_pinky_intermediate_joint" type="revolute">
    <origin xyz="-0.0024229 0.032041 -0.001" rpy="0 0 0"/>
    <parent link="R_pinky_proximal"/>
    <child link="R_pinky_intermediate"/>
    <axis xyz="0 0 1"/>
    <limit lower="0" upper="1.7" effort="1" velocity="0.5"/>
    <mimic joint="R_pinky_proximal_joint" multiplier="1" offset="0"/>
  </joint>

</robot>