<robot name="H2">

  <material name="dark">
    <color rgba="0.4 0.4 0.4 1"/>
  </material>
  <material name="white">
    <color rgba="0.7 0.7 0.7 1"/>
  </material>

  <mujoco>
    <compiler meshdir="meshes" discardvisual="false"/>
  </mujoco>

  <!-- <link name="world"></link>
  <joint name="floating_base_joint" type="floating">
    <parent link="world"/>
    <child link="pelvis"/>
  </joint> -->

  <link name="pelvis">
    <inertial>
      <origin xyz="0.00046244 -0.00004214 -0.01473435" rpy="0 0 0"/>
      <mass value="7.60468095"/>
      <inertia ixx="0.03548205" ixy="-0.00060277" ixz="0.00014978" iyy="0.02290677" iyz="-0.00000038" izz="0.02753519"/>
    </inertial>
    <visual>
      <origin xyz="0 0 0" rpy="0 0 0"/>
      <geometry>
        <mesh filename="meshes/pelvis.stl"/>
      </geometry>
      <material name="white"/>
    </visual>
    <collision>
      <origin xyz="0 0 0" rpy="0 0 0"/>
      <geometry>
        <mesh filename="meshes/pelvis.stl"/>
      </geometry>
    </collision>
  </link>
  <link name="waist_yaw_link">
    <inertial>
      <origin xyz="0.00626994 0 0.01696958" rpy="0 0 0"/>
      <mass value="0.27976220"/>
      <inertia ixx="0.00012352" ixy="0.00000000" ixz="0.00000569" iyy="0.00024730" iyz="0.00000000" izz="0.00031125"/>
    </inertial>
    <visual>
      <origin xyz="0 0 0" rpy="0 0 0"/>
      <geometry>
        <mesh filename="meshes/waist_yaw_link.stl"/>
      </geometry>
      <material name="white"/>
    </visual>
    <!-- <collision>
      <origin xyz="0 0 0" rpy="0 0 0"/>
      <geometry>
        <mesh filename="meshes/waist_yaw_link.stl"/>
      </geometry>
    </collision> -->
  </link>
  <joint name="waist_yaw_joint" type="revolute">
    <origin xyz="0 0.0015099 0.090537" rpy="0 0 0"/>
    <parent link="pelvis"/>
    <child link="waist_yaw_link"/>
    <axis xyz="0 0 1"/>
    <limit lower="-1.7453" upper="1.7453" effort="120" velocity="28.375"/>
  </joint>
  <link name="waist_roll_link">
    <inertial>
      <origin xyz="0.00000000 0.00128474 0.00000000" rpy="0 0 0"/>
      <mass value="0.06585040"/>
      <inertia ixx="0.00000809" ixy="0.00000000" ixz="0.00000000" iyy="0.00001041" iyz="0.00000000" izz="0.00001580"/>
    </inertial>
    <visual>
      <origin xyz="0 0 0" rpy="0 0 0"/>
      <geometry>
        <mesh filename="meshes/waist_roll_link.stl"/>
      </geometry>
      <material name="white"/>
    </visual>
    <!-- <collision>
      <origin xyz="0 0 0" rpy="0 0 0"/>
      <geometry>
        <mesh filename="meshes/waist_roll_link.stl"/>
      </geometry>
    </collision> -->
  </link>
  <joint name="waist_roll_joint" type="revolute">
    <origin xyz="0 -0.0015099 0.0325" rpy="0 0 0"/>
    <parent link="waist_yaw_link"/>
    <child link="waist_roll_link"/>
    <axis xyz="1 0 0"/>
    <limit lower="-0.5236" upper="0.5236" effort="180" velocity="28.375"/>
  </joint>
  <link name="torso_link">
    <inertial>
      <origin xyz="0.01342470 0.00547190 0.21050133" rpy="0 0 0"/>
      <mass value="15.87026294"/>
      <inertia ixx="0.27305029" ixy="0.00013871" ixz="-0.00147103" iyy="0.24363561" iyz="-0.01093518" izz="0.08484661"/>
    </inertial>
    <visual>
      <origin xyz="0 0 0" rpy="0 0 0"/>
      <geometry>
        <mesh filename="meshes/torso_link.stl"/>
      </geometry>
      <material name="white"/>
    </visual>
    <collision>
      <origin xyz="0 0 0" rpy="0 0 0"/>
      <geometry>
        <mesh filename="meshes/torso_link.stl"/>
      </geometry>
    </collision>
  </link>
  <joint name="waist_pitch_joint" type="revolute">
    <origin xyz="0 0 0" rpy="0 0 0"/>
    <parent link="waist_roll_link"/>
    <child link="torso_link"/>
    <axis xyz="0 1 0"/>
    <limit lower="-0.43633" upper="0.5236" effort="180" velocity="28.375"/>
  </joint>
  <link name="head_pitch_link">
    <inertial>
      <origin xyz="5.279E-08 -0.00035318 0.045125" rpy="0 0 0"/>
      <mass value="1.82"/>
      <inertia ixx="0.005386858" ixy="-0.000000033" ixz="0.000020867" iyy="0.005324406" iyz="-0.000007491" izz="0.001409942"/>
    </inertial>
    <visual>
      <origin xyz="0 0 0" rpy="0 0 0"/>
      <geometry>
        <mesh filename="meshes/head_pitch_link.stl"/>
      </geometry>
      <material name="white"/>
    </visual>
    <!-- <collision>
      <origin xyz="0 0 0" rpy="0 0 0"/>
      <geometry>
        <mesh filename="meshes/head_pitch_link.stl"/>
      </geometry>
    </collision> -->
  </link>
  <joint name="head_pitch_joint" type="revolute">
    <origin xyz="-0.00011475 0.020709 0.42181" rpy="0 0 0"/>
    <parent link="torso_link"/>
    <child link="head_pitch_link"/>
    <axis xyz="0 1 0"/>
    <limit lower="-0.5236" upper="0.83775" effort="50" velocity="10"/>
  </joint>
  <link name="head_yaw_link">
    <inertial>
      <origin xyz="0.0219 0 0.0187" rpy="0 0 0"/>
      <mass value="1.3"/>
      <inertia ixx="0.004367405" ixy="-0.00000739" ixz="0.000456883" iyy="0.005352667" iyz="0.000007463" izz="0.004136928"/>
    </inertial>
    <visual>
      <origin xyz="0 0 0" rpy="0 0 0"/>
      <geometry>
        <mesh filename="meshes/head_yaw_link.stl"/>
      </geometry>
      <material name="white"/>
    </visual>
    <collision>
      <origin xyz="0 0 0" rpy="0 0 0"/>
      <geometry>
        <mesh filename="meshes/head_yaw_link.stl"/>
      </geometry>
    </collision>
  </link>
  <joint name="head_yaw_joint" type="revolute">
    <origin xyz="0 -0.0189 0.1325" rpy="0 0 0"/>
    <parent link="head_pitch_link"/>
    <child link="head_yaw_link"/>
    <axis xyz="0 0 1"/>
    <limit lower="-1.7453" upper="1.7453" effort="50" velocity="10"/>
  </joint>
  <link name="right_shoulder_pitch_link">
    <inertial>
      <origin xyz="0.00296153 -0.05202683 -0.02504502" rpy="0 0 0"/>
      <mass value="1.06055553"/>
      <inertia ixx="0.00121801" ixy="0.00002744" ixz="0.00004648" iyy="0.00090494" iyz="-0.00029813" izz="0.00066362"/>
    </inertial>
    <visual>
      <origin xyz="0 0 0" rpy="0 0 0"/>
      <geometry>
        <mesh filename="meshes/right_shoulder_pitch_link.stl"/>
      </geometry>
      <material name="white"/>
    </visual>
    <collision>
      <origin xyz="0 0 0" rpy="0 0 0"/>
      <geometry>
        <mesh filename="meshes/right_shoulder_pitch_link.stl"/>
      </geometry>
    </collision>
  </link>
  <joint name="right_shoulder_pitch_joint" type="revolute">
    <origin xyz="0.0019706 -0.11185 0.35789" rpy="-0.26914 0 0"/>
    <parent link="torso_link"/>
    <child link="right_shoulder_pitch_link"/>
    <axis xyz="0 1 0"/>
    <limit lower="-2.6179939" upper="1.8325957" effort="120" velocity="28.375"/>
  </joint>
  <link name="right_shoulder_roll_link">
    <inertial>
      <origin xyz="0 -0.00415443 -0.06294221" rpy="0 0 0"/>
      <mass value="1.34511054"/>
      <inertia ixx="0.00191998" ixy="-0.00000294" ixz="-0.00023793" iyy="0.00210021" iyz="-0.00004035" izz="0.00112386"/>
    </inertial>
    <visual>
      <origin xyz="0 0 0" rpy="0 0 0"/>
      <geometry>
        <mesh filename="meshes/right_shoulder_roll_link.stl"/>
      </geometry>
      <material name="white"/>
    </visual>
    <collision>
      <origin xyz="0 0 0" rpy="0 0 0"/>
      <geometry>
        <mesh filename="meshes/right_shoulder_roll_link.stl"/>
      </geometry>
    </collision>
  </link>
  <joint name="right_shoulder_roll_joint" type="revolute">
    <origin xyz="-0.00082577 -0.060403 -0.040059" rpy="0.26914 0 0"/>
    <parent link="right_shoulder_pitch_link"/>
    <child link="right_shoulder_roll_link"/>
    <axis xyz="1 0 0"/>
    <limit lower="-2.6354472" upper="0.5166175" effort="54" velocity="34.3"/>
  </joint>
  <link name="right_shoulder_yaw_link">
    <inertial>
      <origin xyz="0.00364187 -0.01865147 -0.05585548" rpy="0 0 0"/>
      <mass value="0.91571732"/>
      <inertia ixx="0.00304064" ixy="-0.00001983" ixz="0.00018692" iyy="0.00254925" iyz="0.00016348" izz="0.00147669"/>
    </inertial>
    <visual>
      <origin xyz="0 0 0" rpy="0 0 0"/>
      <geometry>
        <mesh filename="meshes/right_shoulder_yaw_link.stl"/>
      </geometry>
      <material name="white"/>
    </visual>
    <collision>
      <origin xyz="0 0 0" rpy="0 0 0"/>
      <geometry>
        <mesh filename="meshes/right_shoulder_yaw_link.stl"/>
      </geometry>
    </collision>
  </link>
  <joint name="right_shoulder_yaw_joint" type="revolute">
    <origin xyz="-0.0025949 -0.0037808 -0.096231" rpy="0 0 0"/>
    <parent link="right_shoulder_roll_link"/>
    <child link="right_shoulder_yaw_link"/>
    <axis xyz="0 0 1"/>
    <limit lower="-2.6179939" upper="2.6179939" effort="54" velocity="34.3"/>
  </joint>
  <link name="right_elbow_link">
    <inertial>
      <origin xyz="0.04599687 0.02832961 -0.00661325" rpy="0 0 0"/>
      <mass value="1.69431869"/>
      <inertia ixx="0.00071506" ixy="-0.00027494" ixz="0.00013832" iyy="0.00547116" iyz="0.00001668" izz="0.00533470"/>
    </inertial>
    <visual>
      <origin xyz="0 0 0" rpy="0 0 0"/>
      <geometry>
        <mesh filename="meshes/right_elbow_link.stl"/>
      </geometry>
      <material name="white"/>
    </visual>
    <collision>
      <origin xyz="0 0 0" rpy="0 0 0"/>
      <geometry>
        <mesh filename="meshes/right_elbow_link.stl"/>
      </geometry>
    </collision>
  </link>
  <joint name="right_elbow_joint" type="revolute">
    <origin xyz="0.015346 -0.020599 -0.13363" rpy="0 0 0"/>
    <parent link="right_shoulder_yaw_link"/>
    <child link="right_elbow_link"/>
    <axis xyz="0 1 0"/>
    <limit lower="-0.986111" upper="3.0717795" effort="54" velocity="34.3"/>
  </joint>
  <link name="right_wrist_roll_link">
    <inertial>
      <origin xyz="0.03371947 -0.00237482 0.00031544" rpy="0 0 0"/>
      <mass value="0.96983674"/>
      <inertia ixx="0.00087762" ixy="0.00002554" ixz="-0.00000226" iyy="0.00087920" iyz="-0.00000022" izz="0.00092684"/>
    </inertial>
    <visual>
      <origin xyz="0 0 0" rpy="0 0 0"/>
      <geometry>
        <mesh filename="meshes/right_wrist_roll_link.stl"/>
      </geometry>
      <material name="white"/>
    </visual>
    <!-- <collision>
      <origin xyz="0 0 0" rpy="0 0 0"/>
      <geometry>
        <mesh filename="meshes/right_wrist_roll_link.stl"/>
      </geometry>
    </collision> -->
  </link>
  <joint name="right_wrist_roll_joint" type="revolute">
    <origin xyz="0.13177 0.021197 -0.013782" rpy="0 0 0"/>
    <parent link="right_elbow_link"/>
    <child link="right_wrist_roll_link"/>
    <axis xyz="1 0 0"/>
    <limit lower="-2.6179939" upper="2.6179939" effort="54" velocity="34.3"/>
  </joint>
  <link name="right_wrist_pitch_link">
    <inertial>
      <origin xyz="0.01820997 -0.03140354 0.01156873" rpy="0 0 0"/>
      <mass value="0.94695328"/>
      <inertia ixx="0.00087455" ixy="-0.00001140" ixz="0.00009847" iyy="0.00082105" iyz="0.00000641" izz="0.00069205"/>
    </inertial>
    <visual>
      <origin xyz="0 0 0" rpy="0 0 0"/>
      <geometry>
        <mesh filename="meshes/right_wrist_pitch_link.stl"/>
      </geometry>
      <material name="white"/>
    </visual>
    <!-- <collision>
      <origin xyz="0 0 0" rpy="0 0 0"/>
      <geometry>
        <mesh filename="meshes/right_wrist_pitch_link.stl"/>
      </geometry>
    </collision> -->
  </link>
  <joint name="right_wrist_pitch_joint" type="revolute">
    <origin xyz="0.076351 -0.00015864 0.0011464" rpy="0 0 0"/>
    <parent link="right_wrist_roll_link"/>
    <child link="right_wrist_pitch_link"/>
    <axis xyz="0 1 0"/>
    <limit lower="-0.4363323" upper="0.4363323" effort="25" velocity="50.125"/>
  </joint>
  <link name="right_wrist_yaw_link">
    <inertial>
      <origin xyz="-0.01011731 -0.00400457 -0.01730713" rpy="0 0 0"/>
      <mass value="0.60575230"/>
      <inertia ixx="0.00024292" ixy="-0.00002474" ixz="0.00003864" iyy="0.00076758" iyz="0.00003303" izz="0.00067790"/>
    </inertial>
    <visual>
      <origin xyz="0 0 0" rpy="0 0 0"/>
      <geometry>
        <mesh filename="meshes/right_wrist_yaw_link.stl"/>
      </geometry>
      <material name="white"/>
    </visual>
    <collision>
      <origin xyz="0 0 0" rpy="0 0 0"/>
      <geometry>
        <mesh filename="meshes/right_wrist_yaw_link.stl"/>
      </geometry>
    </collision>
  </link>
  <joint name="right_wrist_yaw_joint" type="revolute">
    <origin xyz="0.028195 5.8414E-05 -0.0012184" rpy="0 0 0"/>
    <parent link="right_wrist_pitch_link"/>
    <child link="right_wrist_yaw_link"/>
    <axis xyz="0 0 1"/>
    <limit lower="-1.2217305" upper="1.2217305" effort="25" velocity="50.125"/>
  </joint>
  <link name="left_shoulder_pitch_link">
    <inertial>
      <origin xyz="0.00296153 0.05202683 -0.02504502" rpy="0 0 0"/>
      <mass value="1.06055553"/>
      <inertia ixx="0.00121801" ixy="-0.000027444" ixz="0.00004648" iyy="0.00090494" iyz="0.00029813" izz="0.00066362"/>
    </inertial>
    <visual>
      <origin xyz="0 0 0" rpy="0 0 0"/>
      <geometry>
        <mesh filename="meshes/left_shoulder_pitch_link.stl"/>
      </geometry>
      <material name="white"/>
    </visual>
    <collision>
      <origin xyz="0 0 0" rpy="0 0 0"/>
      <geometry>
        <mesh filename="meshes/left_shoulder_pitch_link.stl"/>
      </geometry>
    </collision>
  </link>
  <joint name="left_shoulder_pitch_joint" type="revolute">
    <origin xyz="0.0019779 0.11553 0.35792" rpy="0.26914 0 0"/>
    <parent link="torso_link"/>
    <child link="left_shoulder_pitch_link"/>
    <axis xyz="0 1 0"/>
    <limit lower="-2.6179939" upper="1.8325957" effort="120" velocity="28.375"/>
  </joint>
  <link name="left_shoulder_roll_link">
    <inertial>
      <origin xyz="0 0.00415443 -0.06294221" rpy="0 0 0"/>
      <mass value="1.34511054"/>
      <inertia ixx="0.00191998" ixy="0.00000294" ixz="-0.00023793" iyy="0.00210021" iyz="0.00004035" izz="0.00112386"/>
    </inertial>
    <visual>
      <origin xyz="0 0 0" rpy="0 0 0"/>
      <geometry>
        <mesh filename="meshes/left_shoulder_roll_link.stl"/>
      </geometry>
      <material name="white"/>
    </visual>
    <collision>
      <origin xyz="0 0 0" rpy="0 0 0"/>
      <geometry>
        <mesh filename="meshes/left_shoulder_roll_link.stl"/>
      </geometry>
    </collision>
  </link>
  <joint name="left_shoulder_roll_joint" type="revolute">
    <origin xyz="-0.00082158 0.060413 -0.040043" rpy="-0.26914 0 0"/>
    <parent link="left_shoulder_pitch_link"/>
    <child link="left_shoulder_roll_link"/>
    <axis xyz="1 0 0"/>
    <limit lower="-0.5166175" upper="2.6354472" effort="54" velocity="34.3"/>
  </joint>
  <link name="left_shoulder_yaw_link">
    <inertial>
      <origin xyz="0.00364187 0.01865147 -0.05585548" rpy="0 0 0"/>
      <mass value="0.91571732"/>
      <inertia ixx="0.00304064" ixy="0.00001983" ixz="0.00018692" iyy="0.00254925" iyz="-0.00016348" izz="0.00147669"/>
    </inertial>
    <visual>
      <origin xyz="0 0 0" rpy="0 0 0"/>
      <geometry>
        <mesh filename="meshes/left_shoulder_yaw_link.stl"/>
      </geometry>
      <material name="white"/>
    </visual>
    <collision>
      <origin xyz="0 0 0" rpy="0 0 0"/>
      <geometry>
        <mesh filename="meshes/left_shoulder_yaw_link.stl"/>
      </geometry>
    </collision>
  </link>
  <joint name="left_shoulder_yaw_joint" type="revolute">
    <origin xyz="-0.0025946 0.0038061 -0.09623" rpy="0 0 0"/>
    <parent link="left_shoulder_roll_link"/>
    <child link="left_shoulder_yaw_link"/>
    <axis xyz="0 0 1"/>
    <limit lower="-2.6179939" upper="2.6179939" effort="54" velocity="34.3"/>
  </joint>
  <link name="left_elbow_link">
    <inertial>
      <origin xyz="0.04599687 -0.02832961 -0.00661325" rpy="0 0 0"/>
      <mass value="1.69431869"/>
      <inertia ixx="0.00071506" ixy="0.00027494" ixz="0.00013832" iyy="0.00547116" iyz="-0.00001668" izz="0.00533470"/>
    </inertial>
    <visual>
      <origin xyz="0 0 0" rpy="0 0 0"/>
      <geometry>
        <mesh filename="meshes/left_elbow_link.stl"/>
      </geometry>
      <material name="white"/>
    </visual>
    <collision>
      <origin xyz="0 0 0" rpy="0 0 0"/>
      <geometry>
        <mesh filename="meshes/left_elbow_link.stl"/>
      </geometry>
    </collision>
  </link>
  <joint name="left_elbow_joint" type="revolute">
    <origin xyz="0.015424 0.020635 -0.13364" rpy="0 0 0"/>
    <parent link="left_shoulder_yaw_link"/>
    <child link="left_elbow_link"/>
    <axis xyz="0 1 0"/>
    <limit lower="-0.986111" upper="3.0717795" effort="54" velocity="34.3"/>
  </joint>
  <link name="left_wrist_roll_link">
    <inertial>
      <origin xyz="0.03371947 0.00237482 0.00031544" rpy="0 0 0"/>
      <mass value="0.96983674"/>
      <inertia ixx="0.00087762" ixy="-0.00002554" ixz="-0.00000226" iyy="0.00087920" iyz="0.00000022" izz="0.00092684"/>
    </inertial>
    <visual>
      <origin xyz="0 0 0" rpy="0 0 0"/>
      <geometry>
        <mesh filename="meshes/left_wrist_roll_link.stl"/>
      </geometry>
      <material name="white"/>
    </visual>
    <!-- <collision>
      <origin xyz="0 0 0" rpy="0 0 0"/>
      <geometry>
        <mesh filename="meshes/left_wrist_roll_link.stl"/>
      </geometry>
    </collision> -->
  </link>
  <joint name="left_wrist_roll_joint" type="revolute">
    <origin xyz="0.13119 -0.021207 -0.013343" rpy="0 0 0"/>
    <parent link="left_elbow_link"/>
    <child link="left_wrist_roll_link"/>
    <axis xyz="1 0 0"/>
    <limit lower="-2.6179939" upper="2.6179939" effort="54" velocity="34.3"/>
  </joint>
  <link name="left_wrist_pitch_link">
    <inertial>
      <origin xyz="0.01820997 0.03140354 0.01156873" rpy="0 0 0"/>
      <mass value="0.94695328"/>
      <inertia ixx="0.00087455" ixy="0.00001140" ixz="0.00009847" iyy="0.00082105" iyz="-0.00000641" izz="0.00069205"/>
    </inertial>
    <visual>
      <origin xyz="0 0 0" rpy="0 0 0"/>
      <geometry>
        <mesh filename="meshes/left_wrist_pitch_link.stl"/>
      </geometry>
      <material name="white"/>
    </visual>
    <!-- <collision>
      <origin xyz="0 0 0" rpy="0 0 0"/>
      <geometry>
        <mesh filename="meshes/left_wrist_pitch_link.stl"/>
      </geometry>
    </collision> -->
  </link>
  <joint name="left_wrist_pitch_joint" type="revolute">
    <origin xyz="0.080589 3.0398E-05 -0.0013317" rpy="0 0 0"/>
    <parent link="left_wrist_roll_link"/>
    <child link="left_wrist_pitch_link"/>
    <axis xyz="0 1 0"/>
    <limit lower="-0.4363323" upper="0.4363323" effort="25" velocity="50.125"/>
  </joint>
  <link name="left_wrist_yaw_link">
    <inertial>
      <origin xyz="-0.01011731 0.00400457 -0.01730713" rpy="0 0 0"/>
      <mass value="0.60575230"/>
      <inertia ixx="0.00024292" ixy="0.00002474" ixz="0.00003864" iyy="0.00076758" iyz="-0.00003303" izz="0.00067790"/>
    </inertial>
    <visual>
      <origin xyz="0 0 0" rpy="0 0 0"/>
      <geometry>
        <mesh filename="meshes/left_wrist_yaw_link.stl"/>
      </geometry>
      <material name="white"/>
    </visual>
    <collision>
      <origin xyz="0 0 0" rpy="0 0 0"/>
      <geometry>
        <mesh filename="meshes/left_wrist_yaw_link.stl"/>
      </geometry>
    </collision>
  </link>
  <joint name="left_wrist_yaw_joint" type="revolute">
    <origin xyz="0.028225 0.00048901 0.00058318" rpy="0 0 0"/>
    <parent link="left_wrist_pitch_link"/>
    <child link="left_wrist_yaw_link"/>
    <axis xyz="0 0 1"/>
    <limit lower="-1.2217305" upper="1.2217305" effort="25" velocity="50.125"/>
  </joint>
  <link name="left_hip_pitch_link">
    <inertial>
      <origin xyz="0.00300595 0.05931469 -0.01709150" rpy="0 0 0"/>
      <mass value="2.79752530"/>
      <inertia ixx="0.00509731" ixy="-0.00008393" ixz="0.00004539" iyy="0.00371022" iyz="0.00030980" izz="0.00385560"/>
    </inertial>
    <visual>
      <origin xyz="0 0 0" rpy="0 0 0"/>
      <geometry>
        <mesh filename="meshes/left_hip_pitch_link.stl"/>
      </geometry>
      <material name="white"/>
    </visual>
    <!-- <collision>
      <origin xyz="0 0 0" rpy="0 0 0"/>
      <geometry>
        <mesh filename="meshes/left_hip_pitch_link.stl"/>
      </geometry>
    </collision> -->
  </link>
  <joint name="left_hip_pitch_joint" type="revolute">
    <origin xyz="0 0.0819279 -0.043723" rpy="-0.5236 0 0"/>
    <parent link="pelvis"/>
    <child link="left_hip_pitch_link"/>
    <axis xyz="0 1 0"/>
    <limit lower="-2.4525975" upper="2.7754225" effort="360" velocity="20"/>
  </joint>
  <link name="left_hip_roll_link">
    <inertial>
      <origin xyz="-0.03026193 -0.00468930 -0.04449852" rpy="0 0 0"/>
      <mass value="0.62714607"/>
      <inertia ixx="0.00130633" ixy="-0.00000552" ixz="-0.00013133" iyy="0.00168791" iyz="-0.00006773" izz="0.00196361"/>
    </inertial>
    <visual>
      <origin xyz="0 0 0" rpy="0 0 0"/>
      <geometry>
        <mesh filename="meshes/left_hip_roll_link.stl"/>
      </geometry>
      <material name="white"/>
    </visual>
    <collision>
      <origin xyz="-0.020 0 0" rpy="0 0 0"/>
      <geometry>
        <sphere radius="0.05"/>
      </geometry>
    </collision>
  </link>
  <joint name="left_hip_roll_joint" type="revolute">
    <origin xyz="0.018422 0.0635 -0.022095" rpy="0.5236 0 0"/>
    <parent link="left_hip_pitch_link"/>
    <child link="left_hip_roll_link"/>
    <axis xyz="1 0 0"/>
    <limit lower="-0.467441" upper="2.1688605" effort="360" velocity="20"/>
  </joint>
  <link name="left_hip_yaw_link">
    <inertial>
      <origin xyz="0.00069408 -0.01086587 -0.11301456" rpy="0 0 0"/>
      <mass value="7.08752046"/>
      <inertia ixx="0.05057956" ixy="-0.00005547" ixz="0.00146675" iyy="0.05110490" iyz="-0.00312202" izz="0.01331946"/>
    </inertial>
    <visual>
      <origin xyz="0 0 0" rpy="0 0 0"/>
      <geometry>
        <mesh filename="meshes/left_hip_yaw_link.stl"/>
      </geometry>
      <material name="white"/>
    </visual>
    <collision>
      <origin xyz="0 0 0" rpy="0 0 0"/>
      <geometry>
        <mesh filename="meshes/left_hip_yaw_link.stl"/>
      </geometry>
    </collision>
  </link>
  <joint name="left_hip_yaw_joint" type="revolute">
    <origin xyz="-0.0047433 -0.0057328 -0.075875" rpy="0 0 0"/>
    <parent link="left_hip_roll_link"/>
    <child link="left_hip_yaw_link"/>
    <axis xyz="0 0 1"/>
    <limit lower="-2.827" upper="2.827" effort="360" velocity="20"/>
  </joint>
  <link name="left_knee_link">
    <inertial>
      <origin xyz="0.00461331 0 -0.16715459" rpy="0 0 0"/>
      <mass value="3.55340244"/>
      <inertia ixx="0.05108514" ixy="-0.00000720" ixz="-0.00041631" iyy="0.05123842" iyz="0.00001339" izz="0.00334361"/>
    </inertial>
    <visual>
      <origin xyz="0 0 0" rpy="0 0 0"/>
      <geometry>
        <mesh filename="meshes/left_knee_link.stl"/>
      </geometry>
      <material name="white"/>
    </visual>
    <collision>
      <origin xyz="0.01 0 -0.25" rpy="0 0 0"/>
      <geometry>
        <cylinder radius="0.025" length="0.35"/>
      </geometry>
    </collision>
  </link>
  <joint name="left_knee_joint" type="revolute">
    <origin xyz="-0.010386 -0.0042181 -0.31742" rpy="0 0 0"/>
    <parent link="left_hip_yaw_link"/>
    <child link="left_knee_link"/>
    <axis xyz="0 1 0"/>
    <limit lower="-0.08725" upper="2.53025" effort="360" velocity="20"/>
  </joint>
  <link name="left_ankle_roll_link">
    <inertial>
      <origin xyz="-0.01740632 0.00006424 -0.00021460" rpy="0 0 0"/>
      <mass value="0.12318157"/>
      <inertia ixx="0.00003432" ixy="0.00000012" ixz="0.00000002" iyy="0.00001450" iyz="-0.00000002" izz="0.00004005"/>
    </inertial>
    <visual>
      <origin xyz="0 0 0" rpy="0 0 0"/>
      <geometry>
        <mesh filename="meshes/left_ankle_roll_link.stl"/>
      </geometry>
      <material name="white"/>
    </visual>
    <!-- <collision>
      <origin xyz="0 0 0" rpy="0 0 0"/>
      <geometry>
        <mesh filename="meshes/left_ankle_roll_link.stl"/>
      </geometry>
    </collision> -->
  </link>
  <joint name="left_ankle_roll_joint" type="revolute">
    <origin xyz="0.018383 0 -0.49662" rpy="0 0 0"/>
    <parent link="left_knee_link"/>
    <child link="left_ankle_roll_link"/>
    <axis xyz="1 0 0"/>
    <limit lower="-0.3490658503" upper="0.296705972783" effort="19" velocity="100.7"/>
  </joint>
  <link name="left_ankle_pitch_link">
    <inertial>
      <origin xyz="0.03205900 0.03700531 -0.02882818" rpy="0 0 0"/>
      <mass value="0.84496747"/>
      <inertia ixx="0.00060825" ixy="0.00000046" ixz="0.00017671" iyy="0.00410964" iyz="-0.00000001" izz="0.00437490"/>
    </inertial>
    <visual>
      <origin xyz="0 0 0" rpy="0 0 0"/>
      <geometry>
        <mesh filename="meshes/left_ankle_pitch_link.stl"/>
      </geometry>
      <material name="white"/>
    </visual>
    <collision>
      <origin xyz="0 0 0" rpy="0 0 0"/>
      <geometry>
        <mesh filename="meshes/left_ankle_pitch_link.stl"/>
      </geometry>
    </collision>
  </link>
  <joint name="left_ankle_pitch_joint" type="revolute">
    <origin xyz="0 -0.0368 0" rpy="0 0 0"/>
    <parent link="left_ankle_roll_link"/>
    <child link="left_ankle_pitch_link"/>
    <axis xyz="0 1 0"/>
    <limit lower="-1.13446401358" upper="0.61086523808" effort="66.88" velocity="28.61"/>
  </joint>
  <link name="right_hip_pitch_link">
    <inertial>
      <origin xyz="0.00300595 -0.05931469 -0.01709150" rpy="0 0 0"/>
      <mass value="2.79752530"/>
      <inertia ixx="0.00509731" ixy="0.00008393" ixz="0.00004539" iyy="0.00371022" iyz="-0.00030980" izz="0.00385560"/>
    </inertial>
    <visual>
      <origin xyz="0 0 0" rpy="0 0 0"/>
      <geometry>
        <mesh filename="meshes/right_hip_pitch_link.stl"/>
      </geometry>
      <material name="white"/>
    </visual>
    <!-- <collision>
      <origin xyz="0 0 0" rpy="0 0 0"/>
      <geometry>
        <mesh filename="meshes/right_hip_pitch_link.stl"/>
      </geometry>
    </collision> -->
  </link>
  <joint name="right_hip_pitch_joint" type="revolute">
    <origin xyz="0 -0.0803801 -0.046403" rpy="0.5236 0 0"/>
    <parent link="pelvis"/>
    <child link="right_hip_pitch_link"/>
    <axis xyz="0 1 0"/>
    <limit lower="-2.4525975" upper="2.7754225" effort="360" velocity="20"/>
  </joint>
  <link name="right_hip_roll_link">
    <inertial>
      <origin xyz="-0.03026193 0.00468930 -0.04449852" rpy="0 0 0"/>
      <mass value="0.62714607"/>
      <inertia ixx="0.00130633" ixy="0.00000552" ixz="-0.00013133" iyy="0.00168791" iyz="0.00006773" izz="0.00196361"/>
    </inertial>
    <visual>
      <origin xyz="0 0 0" rpy="0 0 0"/>
      <geometry>
        <mesh filename="meshes/right_hip_roll_link.stl"/>
      </geometry>
      <material name="white"/>
    </visual>
    <collision>
      <origin xyz="-0.038 0 0" rpy="0 0 0"/>
      <geometry>
        <sphere radius="0.05"/>
      </geometry>
    </collision>
  </link>
  <joint name="right_hip_roll_joint" type="revolute">
    <origin xyz="0.037774 -0.0635 -0.019" rpy="-0.5236 0 0"/>
    <parent link="right_hip_pitch_link"/>
    <child link="right_hip_roll_link"/>
    <axis xyz="1 0 0"/>
    <limit lower="-2.1688605" upper="0.467441" effort="360" velocity="20"/>
  </joint>
  <link name="right_hip_yaw_link">
    <inertial>
      <origin xyz="0.00069408 0.01086587 -0.11301456" rpy="0 0 0"/>
      <mass value="7.08752046"/>
      <inertia ixx="0.05057956" ixy="0.00005547" ixz="0.00146675" iyy="0.05110490" iyz="0.00312202" izz="0.01331946"/>
    </inertial>
    <visual>
      <origin xyz="0 0 0" rpy="0 0 0"/>
      <geometry>
        <mesh filename="meshes/right_hip_yaw_link.stl"/>
      </geometry>
      <material name="white"/>
    </visual>
    <collision>
      <origin xyz="0 0 0" rpy="0 0 0"/>
      <geometry>
        <mesh filename="meshes/right_hip_yaw_link.stl"/>
      </geometry>
    </collision>
  </link>
  <joint name="right_hip_yaw_joint" type="revolute">
    <origin xyz="-0.024111 0.0057328 -0.075875" rpy="0 0 0"/>
    <parent link="right_hip_roll_link"/>
    <child link="right_hip_yaw_link"/>
    <axis xyz="0 0 1"/>
    <limit lower="-2.827" upper="2.827" effort="360" velocity="20"/>
  </joint>
  <link name="right_knee_link">
    <inertial>
      <origin xyz="0.00461331 0 -0.16715459" rpy="0 0 0"/>
      <mass value="3.55340244"/>
      <inertia ixx="0.05108514" ixy="0.00000720" ixz="-0.00041631" iyy="0.05123842" iyz="-0.00001339" izz="0.00334361"/>
    </inertial>
    <visual>
      <origin xyz="0 0 0" rpy="0 0 0"/>
      <geometry>
        <mesh filename="meshes/right_knee_link.stl"/>
      </geometry>
      <material name="white"/>
    </visual>
    <collision>
      <origin xyz="0.01 0 -0.25" rpy="0 0 0"/>
      <geometry>
        <cylinder radius="0.025" length="0.35"/>
      </geometry>
    </collision>
  </link>
  <joint name="right_knee_joint" type="revolute">
    <origin xyz="-0.010386 0.0042181 -0.31742" rpy="0 0 0"/>
    <parent link="right_hip_yaw_link"/>
    <child link="right_knee_link"/>
    <axis xyz="0 1 0"/>
    <limit lower="-0.08725" upper="2.53025" effort="360" velocity="20"/>
  </joint>
  <link name="right_ankle_roll_link">
    <inertial>
      <origin xyz="-0.01740632 -0.00006424 -0.00021460" rpy="0 0 0"/>
      <mass value="0.12318157"/>
      <inertia ixx="0.00003432" ixy="-0.00000012" ixz="0.00000002" iyy="0.00001450" iyz="0.00000002" izz="0.00004005"/>
    </inertial>
    <visual>
      <origin xyz="0 0 0" rpy="0 0 0"/>
      <geometry>
        <mesh filename="meshes/right_ankle_roll_link.stl"/>
      </geometry>
      <material name="white"/>
    </visual>
    <!-- <collision>
      <origin xyz="0 0 0" rpy="0 0 0"/>
      <geometry>
        <mesh filename="meshes/right_ankle_roll_link.stl"/>
      </geometry>
    </collision> -->
  </link>
  <joint name="right_ankle_roll_joint" type="revolute">
    <origin xyz="0.018383 0 -0.49662" rpy="0 0 0"/>
    <parent link="right_knee_link"/>
    <child link="right_ankle_roll_link"/>
    <axis xyz="1 0 0"/>
    <limit lower="-0.296705972783" upper="0.3490658503" effort="19" velocity="100.7"/>
  </joint>
  <link name="right_ankle_pitch_link">
    <inertial>
      <origin xyz="0.03205900 -0.03700531 -0.02882818" rpy="0 0 0"/>
      <mass value="0.84496747"/>
      <inertia ixx="0.00060825" ixy="-0.00000046" ixz="0.00017671" iyy="0.00410964" iyz="0.00000001" izz="0.00437490"/>
    </inertial>
    <visual>
      <origin xyz="0 0 0" rpy="0 0 0"/>
      <geometry>
        <mesh filename="meshes/right_ankle_pitch_link.stl"/>
      </geometry>
      <material name="white"/>
    </visual>
    <collision>
      <origin xyz="0 0 0" rpy="0 0 0"/>
      <geometry>
        <mesh filename="meshes/right_ankle_pitch_link.stl"/>
      </geometry>
    </collision>
  </link>
  <joint name="right_ankle_pitch_joint" type="revolute">
    <origin xyz="0 0.0373 0" rpy="0 0 0"/>
    <parent link="right_ankle_roll_link"/>
    <child link="right_ankle_pitch_link"/>
    <axis xyz="0 1 0"/>
    <limit lower="-1.13446401358" upper="0.61086523808" effort="66.88" velocity="28.61"/>
  </joint>
</robot>